Workbook

Sheet Summary
A1: Township Green Loop – Executive Summary
A3: SDP University Hackathon 2026 · Theme: Planet · We run the platform; township developers pay to use it; residents invest in three green pools.
A5: Vendor (us, the platform)
A6: Vendor ROI (5-yr) | C6: Vendor net profit (5-yr) | E6: Vendor NPV
A7: =ROI!C16 -> 1.171918 | C7: =ROI!H10 -> 1434165.2 | E7: =ROI!E31 -> 778498.7
A9: Customer (township developers, all clients)
A10: Customer ROI (5-yr) | C10: Customer net profit (5-yr) | E10: Customer NPV
A11: =ROI!C17 -> 2.3525179 | C11: =ROI!H13 -> 4258510.4 | E11: =ROI!C39 -> 2478279.8
A13: ="Discount rate "&TEXT(Assumptions!$B$58,"0%")&" · ROI = (gain − cost) ÷ cost · Customer = benefit to developers minus what they pay us (Customer_ROI has SDP alone)." -> Discount rate 15% · ROI = (gain − cost) ÷ cost · Customer = benefit to developers minus what they pay us (Customer_ROI has SDP alone).
A15: Investor (resident) view: see the Investor_View sheet (minimum and maximum investment for each pool).
A17: Key takeaways
A18: • SDP gains from Year 1 even on cash alone: Year 1 costs only a RM20,000 set-up instalment, and the JV passes a 1% fee on residents' solar money to SDP. Half of the community saving is guaranteed in the contract.
A19: • Residents earn from Year 1 on solar and upgrades; EV is variable with a minimum-usage top-up.
A20: • We lose money in Year 1 (covered by a RM120,000 grant) and earn from Year 2, even if only one new developer signs that year. See Conservative_Test.
A22: Core prices
A23: ="Set-up fee RM"&TEXT(Assumptions!$B$38,"#,##0")&" (RM"&TEXT(Assumptions!$B$60,"#,##0")&" in Year 1, RM"&TEXT(Assumptions!$B$61,"#,##0")&" in Year 2) · Platform fee RM"&TEXT(Assumptions!$B$39,"#,##0")&" a year from Year 2 · Success fee "&TEXT(Assumptions!$B$40,"0.00%")&" (waived in Year 1) · "&TEXT(Assumptions!$B$41,"0.0%")&" a year on money invested · "&TEXT(Assumptions!$B$42,"0%")&" on mall redemptions · smaller developers pay pro rata" -> Set-up fee RM50,000 (RM20,000 in Year 1, RM30,000 in Year 2) · Platform fee RM72,000 a year from Year 2 · Success fee 0.75% (waived in Year 1) · 0.5% a year on money invested · 2% on mall redemptions · smaller developers pay pro rata
A25: Normal vs conservative (live, from Conservative_Test)
A26: Check | C26: Normal | E26: Conservative | G26: Normal | H26: Conservative
A27: 1. Customer (SDP) net gain, Year 1 | C27: =Conservative_Test!B26 -> 137144.65 | E27: =Conservative_Test!C26 -> 22856.606 | G27: =Conservative_Test!E26 -> PASS | H27: =Conservative_Test!F26 -> PASS
A28: 2. Customer cash-only net gain, Year 1 (no community saving) | C28: =Conservative_Test!B27 -> 33144.65 | E28: =Conservative_Test!C27 -> 22856.606 | G28: =Conservative_Test!E27 -> PASS | H28: =Conservative_Test!F27 -> PASS
A29: 2b. New developer net gain, its Year 1 | C29: =Conservative_Test!B28 -> 82286.79 | E29: =Conservative_Test!C28 -> 9142.6423 | G29: =Conservative_Test!E28 -> PASS | H29: =Conservative_Test!F28 -> PASS
A30: 3. Residents' profit, Year 1 (all pools, SDP) | C30: =Conservative_Test!B29 -> 82163.299 | E30: =Conservative_Test!C29 -> 50465.897 | G30: =Conservative_Test!E29 -> PASS | H30: =Conservative_Test!F29 -> PASS
A31: 4a. Solar investor return, Year 1 | C31: =Conservative_Test!B30 -> 0.04547563 | E31: =Conservative_Test!C30 -> 0.04547563 | G31: =Conservative_Test!E30 -> PASS | H31: =Conservative_Test!F30 -> PASS
A32: 4b. Upgrade investor return, Year 1 | C32: =Conservative_Test!B31 -> 0.05484129 | E32: =Conservative_Test!C31 -> 0.012947272 | G32: =Conservative_Test!E31 -> PASS | H32: =Conservative_Test!F31 -> PASS
A33: 4c. EV investor loss over the 7-year payback period | C33: =Conservative_Test!B32 -> 0 | E33: =Conservative_Test!C32 -> 0.4 | G33: =Conservative_Test!E32 -> PASS | H33: =Conservative_Test!F32 -> PASS
A34: 5. Our net profit, Year 2 | C34: =Conservative_Test!B33 -> 92228.355 | E34: =Conservative_Test!C33 -> 5033.9555 | G34: =Conservative_Test!E33 -> PASS | H34: =Conservative_Test!F33 -> PASS
A35: 6. Our net profit, 5 years | C35: =Conservative_Test!B34 -> 1434165.2 | E35: =Conservative_Test!C34 -> 131171.91 | G35: =Conservative_Test!E34 -> PASS | H35: =Conservative_Test!F34 -> PASS
A36: 7. NPV of our cash flows | C36: =Conservative_Test!B35 -> 778498.7 | E36: =Conservative_Test!C35 -> 22817.907 | G36: =Conservative_Test!E35 -> PASS | H36: =Conservative_Test!F35 -> PASS
A37: 8. Lowest cash balance in 5 years (with grant) | C37: =Conservative_Test!B36 -> 33918.505 | E37: =Conservative_Test!C36 -> 12403.716 | G37: =Conservative_Test!E36 -> PASS | H37: =Conservative_Test!F36 -> PASS
A38: 9. Our lowest yearly net profit, Years 2–5 | C38: =Conservative_Test!B37 -> 92228.355 | E38: =Conservative_Test!C37 -> 5033.9555 | G38: =Conservative_Test!E37 -> PASS | H38: =Conservative_Test!F37 -> PASS
A39: All checks | G39: =Conservative_Test!E38 -> ALL PASS | H39: =Conservative_Test!F38 -> ALL PASS

Sheet Investor_View
A1: Investor_View – what a resident gets from each pool, at the minimum and maximum investment
A2: All numbers link to Investor_ROI and Assumptions. Change the limits in Assumptions rows 96–101.
A4: Per resident | B4: Solar pool (low risk) | D4: Upgrade pool (medium risk) | F4: EV pool (high risk)
B5: Minimum | C5: Maximum | D5: Minimum | E5: Maximum | F5: Minimum | G5: Maximum
A6: Invest | B6: =Assumptions!$B$96 -> 100 | C6: =Assumptions!$B$97 -> 5000 | D6: =Assumptions!$B$98 -> 100 | E6: =Assumptions!$B$99 -> 3000 | F6: =Assumptions!$B$100 -> 100 | G6: =Assumptions!$B$101 -> 1000
A7: Investment rate (per year) | B7: =Investor_ROI!B6 -> 0.05 | C7: =Investor_ROI!B6 -> 0.05 | D7: =Investor_ROI!B15 -> 0.065 | E7: =Investor_ROI!B15 -> 0.065 | F7: =Investor_ROI!B57 -> 0.066187268 | G7: =Investor_ROI!B57 -> 0.066187268
A8: Rate type | B8: Fixed payout backed by tenant power payments (not roof leasing); minimum 4.5% | C8: Fixed payout backed by tenant power payments (not roof leasing); minimum 4.5% | D8: Fixed; installer guarantees shop savings | E8: Fixed; installer guarantees shop savings | F8: Variable, not guaranteed; partners top up to 60 kWh/day (capped) | G8: Variable, not guaranteed; partners top up to 60 kWh/day (capped)
A9: Money paid back over | B9: =Assumptions!$B$20&" years, monthly" -> 5 years, monthly | C9: =Assumptions!$B$20&" years, monthly" -> 5 years, monthly | D9: =Assumptions!$B$27&" years, monthly" -> 3 years, monthly | E9: =Assumptions!$B$27&" years, monthly" -> 3 years, monthly | F9: =Investor_ROI!B30&" years, from charging income" -> 7 years, from charging income | G9: =Investor_ROI!B30&" years, from charging income" -> 7 years, from charging income
A10: Normal case
A11: Total received | B11: =B6*(Investor_ROI!B46)/Investor_ROI!B45 -> 113.2274 | C11: =C6*(Investor_ROI!B46)/Investor_ROI!B45 -> 5661.3701 | D11: =D6*((Investor_ROI!B50-Investor_ROI!B51))/Investor_ROI!B45 -> 110.33641 | E11: =E6*((Investor_ROI!B50-Investor_ROI!B51))/Investor_ROI!B45 -> 3310.0923 | F11: =F6*(Investor_ROI!B55)/Investor_ROI!B45 -> 128.70961 | G11: =G6*(Investor_ROI!B55)/Investor_ROI!B45 -> 1287.0961
A12: Return over the payback period (RM) | B12: =B6*(Investor_ROI!B46)/Investor_ROI!B45-B6 -> 13.227402 | C12: =C6*(Investor_ROI!B46)/Investor_ROI!B45-C6 -> 661.37009 | D12: =D6*((Investor_ROI!B50-Investor_ROI!B51))/Investor_ROI!B45-D6 -> 10.33641 | E12: =E6*((Investor_ROI!B50-Investor_ROI!B51))/Investor_ROI!B45-E6 -> 310.09231 | F12: =F6*(Investor_ROI!B55)/Investor_ROI!B45-F6 -> 28.709607 | G12: =G6*(Investor_ROI!B55)/Investor_ROI!B45-G6 -> 287.09607
A13: Return over the payback period (%) | B13: =(Investor_ROI!B46)/Investor_ROI!B45-1 -> 0.13227402 | C13: =(Investor_ROI!B46)/Investor_ROI!B45-1 -> 0.13227402 | D13: =((Investor_ROI!B50-Investor_ROI!B51))/Investor_ROI!B45-1 -> 0.1033641 | E13: =((Investor_ROI!B50-Investor_ROI!B51))/Investor_ROI!B45-1 -> 0.1033641 | F13: =(Investor_ROI!B55)/Investor_ROI!B45-1 -> 0.28709607 | G13: =(Investor_ROI!B55)/Investor_ROI!B45-1 -> 0.28709607
A14: Conservative case (Scenarios sheet)
A15: Effective rate (per year) | B15: =Investor_ROI!C8 -> 0.05 | C15: =Investor_ROI!C8 -> 0.05 | D15: =Investor_ROI!C53 -> 0.032304876 | E15: =Investor_ROI!C53 -> 0.032304876 | F15: =Investor_ROI!C57 -> -0.11351477 | G15: =Investor_ROI!C57 -> -0.11351477
A16: Total received | B16: =B6*(Investor_ROI!C46)/Investor_ROI!C45 -> 113.2274 | C16: =C6*(Investor_ROI!C46)/Investor_ROI!C45 -> 5661.3701 | D16: =D6*((Investor_ROI!C50-Investor_ROI!C51))/Investor_ROI!C45 -> 105.05843 | E16: =E6*((Investor_ROI!C50-Investor_ROI!C51))/Investor_ROI!C45 -> 3151.7528 | F16: =F6*(Investor_ROI!C55)/Investor_ROI!C45 -> 60 | G16: =G6*(Investor_ROI!C55)/Investor_ROI!C45 -> 600
A17: Return over the payback period (RM) | B17: =B6*(Investor_ROI!C46)/Investor_ROI!C45-B6 -> 13.227402 | C17: =C6*(Investor_ROI!C46)/Investor_ROI!C45-C6 -> 661.37009 | D17: =D6*((Investor_ROI!C50-Investor_ROI!C51))/Investor_ROI!C45-D6 -> 5.0584278 | E17: =E6*((Investor_ROI!C50-Investor_ROI!C51))/Investor_ROI!C45-E6 -> 151.75283 | F17: =F6*(Investor_ROI!C55)/Investor_ROI!C45-F6 -> -40 | G17: =G6*(Investor_ROI!C55)/Investor_ROI!C45-G6 -> -400
A18: Return over the payback period (%) | B18: =(Investor_ROI!C46)/Investor_ROI!C45-1 -> 0.13227402 | C18: =(Investor_ROI!C46)/Investor_ROI!C45-1 -> 0.13227402 | D18: =((Investor_ROI!C50-Investor_ROI!C51))/Investor_ROI!C45-1 -> 0.050584278 | E18: =((Investor_ROI!C50-Investor_ROI!C51))/Investor_ROI!C45-1 -> 0.050584278 | F18: =(Investor_ROI!C55)/Investor_ROI!C45-1 -> -0.4 | G18: =(Investor_ROI!C55)/Investor_ROI!C45-1 -> -0.4
A20: ="Most one resident can put in across all three pools: RM"&TEXT(Assumptions!$B$97+Assumptions!$B$99+Assumptions!$B$101,"#,##0")&". Smallest start: RM"&TEXT(MIN(Assumptions!$B$96,Assumptions!$B$98,Assumptions!$B$100),"#,##0")&" in any one pool." -> Most one resident can put in across all three pools: RM9,000. Smallest start: RM100 in any one pool.
A21: • Payback period: solar 5 years, upgrades 3 years, EV 7 years. Returns are over each pool's own payback period. The return % is the same at the minimum and the maximum; only the RM amount changes.
A22: • Solar: residents are funders, not roof landlords. The developer/JV owns and runs the panels; tenants, malls and factories pay for the power, and residents' payouts are paid first. Different from SDP's CREAM roof-leasing project in Elmina.
A23: • Upgrades: paid back monthly over 3 years. Totals are after expected shop defaults and the bad-debt reserve.
A24: • EV: the thinnest pool. A licensed charge point operator (CPO) co-invests half and runs the chargers. Payouts come only from charging profit; the developer and platform take their 10% shares only after residents get their money back. If usage falls below 60 kWh/day, partners top up (capped at RM3,000 per charger a year). Price wars, cost rises and a refused government grant are NOT covered: in the conservative case residents get back only about 60% of their money.
A25: • Risk disclosure: none of the pools is a deposit and none is covered by PIDM. Money is held by a licensed platform, never by us. The maximum per pool stays within the RM5,000-per-company limit for retail investors [R24].

Sheet Assumptions
A1: Township Green Loop – Business Plan Assumptions
A2: Blue = input you can change · Yellow = key assumption to check · Black = formula · Green sections (rows 59–101) were added in v2; rows 102+ were added in v3 (EV rework, solar positioning). All money in RM.
A4: Input | B4: Value | C4: Unit | D4: Source / note
A5: General
A6: Model Year 1 (calendar year) | B6: 2027 | C6: year | D6: Platform goes live after the hackathon pilot.
A7: Average investment per resident | B7: 500 | C7: RM | D7: Assumption. Each pool has its own minimum and maximum (Assumptions rows 96–101).
A8: Share of resident payouts spent at the developer's malls | B8: 0.3 | C8: % | D8: Assumption. Not survey-validated.
A9: Mall redemption bonus (paid by participating shops as a promotion) | B9: 0.1 | C9: % | D9: Design choice. Shops fund it, so it costs the developer nothing.
A10: Turnover rent the mall earns on extra shop sales | B10: 0.01 | C10: % of sales | D10: Example rate of 1% of gross sales on top of base rent: D&H law firm [R13].
A11: Average electricity tariff | B11: 0.454 | C11: RM/kWh | D11: Average base tariff 45.4 sen/kWh from July 2025 (HLIB via Business Today) [R8].
A12: Grid emission factor, Peninsular Malaysia 2024 | B12: 0.74 | C12: tCO2e/MWh | D12: Energy Commission, GEF 2022–2024 (provisional) [R9].
A13: SDP yearly spend on community programmes and spaces | B13: 20800000 | C13: RM/yr | D13: SDP Integrated Report 2024 key highlights: 70,000+ beneficiaries, RM20.8 million total economic spend [R12].
A14: Share of solar funding saving kept by the developer | B14: 0.5 | C14: % | D14: Assumption. Solar assets sit in the SDP × GSPARX JV [R1]; the JV split was not found in public sources, so 50% is used.
A15: Pool 1 – Rooftop solar (residents fund it; the developer/JV owns and runs it – not roof leasing)
A16: Installed solar cost | B16: 3200 | C16: RM/kWp | D16: v3: 2,800 → 3,200 (commercial system incl. SST, structure and grid works). Prudent: one installer lists commercial 50–100 kWp from RM2,400/kWp before SST [R38]; the RM3,500–4,000 range in the brief was not confirmed.
A17: Solar output per kWp | B17: 1250 | C17: kWh/kWp/yr | D17: 100 kWp commercial roof gives about 120,000–140,000 kWh a year (Trexon) [R5].
A18: Share of each solar asset funded by residents | B18: =Assumptions!$B$111 -> 0.3 | C18: % | D18: v3: links to row 111 (normal 30%); conservative uses row 112 (20%) through Scenarios. Team solar model: at 30%, tenant payments cover payouts 1.83 times [R20].
A19: Payout rate to residents (solar) | B19: 0.05 | C19: % a year | D19: Team solar model. 12-month FD is about 1.9% (ABM, Aug 2026) [R11].
A20: Solar payout tenure | B20: 5 | C20: years | D20: Team solar model.
A21: Return the JV would otherwise need on its own money | B21: 0.085 | C21: % a year | D21: Team solar model project IRR 8.5%; The Edge: mid to high single-digit IRR for solar PPAs [R6].
A22: Pool 2 – Shop energy upgrades
A23: Upgrade cost per shop | B23: 20000 | C23: RM | D23: Assumption (efficient air-con, fridges, LED). Get supplier quotes.
A24: Bill saving per shop | B24: 1000 | C24: RM/month | D24: Assumption: about 25% of a RM4,000 bill. Sunway Pyramid's chiller retrofit beat a 30% energy-cut target [R14].
A25: Share of savings used to repay residents | B25: 0.8 | C25: % | D25: Malaysian ESCO shared-savings cases use 80:20 and 75:25 (MAESCO) [R7].
A26: Payout rate to residents (upgrades) | B26: 0.065 | C26: % a year | D26: Design choice: higher than solar to reflect shop default risk.
A27: Upgrade payout tenure | B27: 3 | C27: years | D27: Design choice.
A28: Developer's share of the monthly safety margin | B28: 0.5 | C28: % | D28: Design choice. Other half kept as a bad-debt reserve.
A29: Pool 3 – EV charging (v3: DC 60 kW + AC 22 kW mix, run by a licensed charge point operator (CPO))
A30: Installed cost per charger, blended DC/AC mix (before grant) | B30: =Assumptions!$B$115*Assumptions!$B$116+(1-Assumptions!$B$115)*Assumptions!$B$117 -> 62500 | C30: RM | D30: v3: formula = DC share × DC cost + AC share × AC cost (rows 115–117). Was 70,000 for one DC charger [R4].
A31: Share of each charger's net cost funded by residents | B31: 0.5 | C31: % | D31: Design choice. v3: the CPO partner co-invests the other 50% and runs the chargers (operations, maintenance, SLA, customer service).
A32: DC 60 kW standard charging price | B32: 1.4 | C32: RM/kWh | D32: v3: 1.29 → 1.40. ChargEV AEON Mall Cheras Selatan: 60 kW DC RM1.40, 22 kW AC RM1.00, 180 kW DC RM1.60 (Jul 2026) [R25]. The brief cited AEON Rawang; the confirmed source is the Cheras Selatan site.
A33: Payment and app costs | B33: 0.03 | C33: % of charging revenue | D33: v3: 10% → 3%. Payment gateway about 1.5–3% plus 1–2% app share (brief; typical gateway range, not separately sourced).
A34: DC 60 kW maintenance and CPO service fee | B34: 10000 | C34: RM/yr | D34: v3: 5,000 → 10,000. US benchmark about US$1,800 a year for a DC fast charger (≈RM7,900) [R32]; 10,000 adds the CPO's SLA and customer service. The brief's '30% of capital a year' is not supported (10,000 is 10% of 100,000).
A35: Energy sold per charger per day | B35: =Assumptions!$B$105*Assumptions!$B$106 -> 60 | C35: kWh/day | D35: v3: 100 → formula = sessions × kWh per session (rows 105–106) = 60. Biggest EV risk: public chargers are mostly AC and utilisation is low [R31].
A36: Developer's share of residents' charging profit (site host) | B36: 0.1 | C36: % | D36: v3: value kept at 10%, but the split is now residents 70% (row 132), developer 10%, platform 10% (row 133), O&M reserve 10% (row 134). Developer and platform shares wait until residents recover their money (row 135).
A37: Vendor pricing (what we charge each developer)
A38: Set-up fee (total, billed over client Years 1 and 2) | B38: =Assumptions!$B$60+Assumptions!$B$61 -> 50000 | C38: RM | D38: v2: formula = Year 1 instalment + Year 2 instalment (rows 60–61).
A39: Annual platform fee (from client's second year) | B39: 72000 | C39: RM/yr | D39: Our price for an SDP-size client (RM6,000 a month, billed monthly). Waived in the first year as a pilot. v2: smaller clients pay pro rata to size.
A40: Success fee on money raised through the platform | B40: 0.0075 | C40: % of raised | D40: Our price. Crowdfunding platforms also charge a success fee on amounts raised (pitchIN) [R15]. v2: waived in client Year 1 (row 62).
A41: Yearly fee on residents' money still invested | B41: 0.005 | C41: % a year | D41: Our price, from client's second year.
...

Sheet Yearly_Inputs
A1: Yearly inputs
A2: Blue = input · Yellow = key assumption. Pool numbers are per client, by the client's year on the platform.
A4: Input | B4: Y1 | C4: Y2 | D4: Y3 | E4: Y4 | F4: Y5 | G4: Unit | H4: Source / note
A5: New solar capacity with a resident share, per client | B5: 3 | C5: 3 | D5: 4 | E5: 5 | F5: 5 | G5: MW | H5: By the client's year on the platform. Reaches 20 MW in 5 years, in line with the SDP × GSPARX JV target of 20 MW in 5 years [R1].
A6: New shops upgraded, per client | B6: 15 | C6: 25 | D6: 10 | E6: 10 | F6: 10 | G6: shops | H6: By the client's year. SDP's 3 malls have about 380 outlets [R2][R3]; only high-energy, low-risk shops qualify (v2: highest-saving shops first).
A7: New EV chargers, per client | B7: 1 | C7: 2 | D7: 2 | E7: 2 | F7: 2 | G7: chargers | H7: By the client's year. v3: 2,4,4,4,4 → 1,2,2,2,2. Start with a 1–2 charger pilot and expand only after 12 months of usage data. High-traffic sites only.
A8: Community-programme saving from digital sign-ups, QR check-ins and auto reports | B8: 0.005 | C8: 0.01 | D8: 0.01 | E8: 0.01 | F8: 0.01 | G8: % of programme spend | H8: Assumption, half in the first year. v2: half of this is guaranteed in the contract (Assumptions rows 64–68).
A9: New developer clients signed (calendar year) | B9: 1 | C9: 2 | D9: 2 | E9: 2 | F9: 2 | G9: clients | H9: Y1 = SDP. Later: other township developers. v2: sign letters of intent in Year 1 for Year 2 clients.
A10: Size of clients joining this year vs SDP | B10: 1 | C10: 0.6 | D10: 0.6 | E10: 0.6 | F10: 0.6 | G10: x SDP | H10: Assumption: later clients are 60% of SDP's size.
A11: Extra developers on payroll (calendar year) | B11: 0 | C11: 0 | D11: 1 | E11: 1 | F11: 2 | G11: people | H11: Hire only once revenue allows.
A12: Part-time support and operations (calendar year) | B12: 0 | C12: 18000 | D12: 36000 | E12: 36000 | F12: 48000 | G12: RM/yr | H12: Assumption.

Sheet Scenarios
A1: Scenarios – conservative stress inputs
A2: Normal values link to Assumptions / Yearly_Inputs. Change the blue Conservative values to re-run the C_ sheets and Conservative_Test.
A4: Stressed input | B4: Normal | C4: Conservative | D4: Change | E4: Why
A5: Community saving actually achieved | B5: =Assumptions!$B$64 -> 1 | C5: 0 | D5: =IF(B5=0,"",C5/B5-1) -> -1 | E5: Benefit E fails completely.
A6: EV energy sold per charger per day (kWh) = sessions × kWh per session | B6: =Assumptions!$B$35 -> 60 | C6: =C15*C16 -> 30 | D6: =IF(B6=0,"",C6/B6-1) -> -0.5 | E6: v3: 30 kWh/day (was 50). Formula from rows 15–16.
A7: Bill saving per shop (RM/month) | B7: =Assumptions!$B$24 -> 1000 | C7: 500 | D7: =IF(B7=0,"",C7/B7-1) -> -0.5 | E7: Upgrades save half as much.
A8: New developer clients signed in Year 2 | B8: =Yearly_Inputs!$C$9 -> 2 | C8: 1 | D8: =IF(B8=0,"",C8/B8-1) -> -0.5 | E8: Only one new client in Year 2.
A9: Developer's share of solar funding saving | B9: =Assumptions!$B$14 -> 0.5 | C9: 0.3 | D9: =IF(B9=0,"",C9/B9-1) -> -0.4 | E9: Weaker JV terms.
A10: Discount rate for NPV | B10: =Assumptions!$B$58 -> 0.15 | C10: 0.2 | D10: =IF(B10=0,"",C10/B10-1) -> 0.33333333 | E10: Higher required return.
A11: Competitor price drop (all charging prices) | B11: =0 -> 0 | C11: 0.2 | D11: =IF(B11=0,"",C11/B11-1) | E11: v3: 10% → 20%. Price war.
A12: Size of new clients vs SDP (Years 2–5) | B12: =Yearly_Inputs!$C$10 -> 0.6 | C12: 0.4 | D12: =IF(B12=0,"",C12/B12-1) -> -0.33333333 | E12: Smaller developers sign up.
A13: Shop default rate (a year) | B13: =Assumptions!$B$73 -> 0.02 | C13: 0.1 | D13: =IF(B13=0,"",C13/B13-1) -> 4 | E13: Five times more shop defaults.
A14: Extra developers hired in Year 3 (our response, not a stress) | B14: =Yearly_Inputs!$D$11 -> 1 | C14: 0 | D14: =IF(B14=0,"",C14/B14-1) -> -1 | E14: Delay the hire when fewer clients sign.
A15: v3 EV: charging sessions per charger per day | B15: =Assumptions!$B$105 -> 2 | C15: 1.5 | D15: =IF(B15=0,"",C15/B15-1) -> -0.25 | E15: Brief said 1 session × 20 kWh, but also 30 kWh/day; 1.5 × 20 keeps both the 20 kWh and the 30 kWh/day.
A16: v3 EV: average kWh per session | B16: =Assumptions!$B$106 -> 30 | C16: 20 | D16: =IF(B16=0,"",C16/B16-1) -> -0.33333333 | E16: Smaller top-ups.
A17: v3 EV: electricity cost increase | B17: =0 -> 0 | C17: 0.2 | D17: =IF(B17=0,"",C17/B17-1) | E17: Tariff or AFA surcharge up 20%.
A18: v3 EV: maintenance cost increase | B18: =0 -> 0 | C18: 0.5 | D18: =IF(B18=0,"",C18/B18-1) | E18: Repairs and parts 50% dearer.
A19: v3 EV: charger downtime | B19: =0 -> 0 | C19: 0.1 | D19: =IF(B19=0,"",C19/B19-1) | E19: Chargers out of service 10% of the time.
A20: v3 EV: MARii grant approved (1 = yes, 0 = no) | B20: =1 -> 1 | C20: 0 | D20: =IF(B20=0,"",C20/B20-1) -> -1 | E20: Grant not approved; residents and CPO fund the full DC cost.
A21: v3 EV: billed idle minutes per charger per day | B21: =Assumptions!$B$124 -> 10 | C21: 5 | D21: =IF(B21=0,"",C21/B21-1) -> -0.5 | E21: Half the idle-fee income.
A22: v3 EV: paying members per charger | B22: =Assumptions!$B$126 -> 10 | C22: 5 | D22: =IF(B22=0,"",C22/B22-1) -> -0.5 | E22: Half the membership income.
A23: v3 Solar: residents' share of each solar asset | B23: =Assumptions!$B$111 -> 0.3 | C23: =Assumptions!$B$112 -> 0.2 | D23: =IF(B23=0,"",C23/B23-1) -> -0.33333333 | E23: Assumptions row 112.
A24: Charging price after drop (RM/kWh) | B24: =Assumptions!$B$32 -> 1.4 | C24: =Assumptions!$B$32*(1-Scenarios!$C$11) -> 1.12

Sheet Pools
A1: Pools – what happens inside one client (SDP size), by the client's year on the platform
A2: Money raised from residents, money still invested, payouts and impact for the three pools. Other clients are scaled from this.
A4: Item | B4: Unit | C4: Year 1 | D4: Year 2 | E4: Year 3 | F4: Year 4 | G4: Year 5
A5: Timing factors (money is raised mid-year on average)
A6: Year since money was raised | C6: 1 | D6: 2 | E6: 3 | F6: 4 | G6: 5
A7: Solar: share of money still owed at year end | C7: =((1+Assumptions!$B$19)^Assumptions!$B$20-(1+Assumptions!$B$19)^C6)/((1+Assumptions!$B$19)^Assumptions!$B$20-1) -> 0.8190252 | D7: =((1+Assumptions!$B$19)^Assumptions!$B$20-(1+Assumptions!$B$19)^D6)/((1+Assumptions!$B$19)^Assumptions!$B$20-1) -> 0.62900166 | E7: =((1+Assumptions!$B$19)^Assumptions!$B$20-(1+Assumptions!$B$19)^E6)/((1+Assumptions!$B$19)^Assumptions!$B$20-1) -> 0.42947695 | F7: =((1+Assumptions!$B$19)^Assumptions!$B$20-(1+Assumptions!$B$19)^F6)/((1+Assumptions!$B$19)^Assumptions!$B$20-1) -> 0.219976 | G7: =((1+Assumptions!$B$19)^Assumptions!$B$20-(1+Assumptions!$B$19)^G6)/((1+Assumptions!$B$19)^Assumptions!$B$20-1) -> 0
A8: Solar: average share still invested | C8: =0.5 -> 0.5 | D8: =(1+C7)/2 -> 0.9095126 | E8: =(C7+D7)/2 -> 0.72401343 | F8: =(D7+E7)/2 -> 0.52923931 | G8: =(E7+F7)/2 -> 0.32472647
A9: Payout timing (half year in first year) | C9: =0.5 -> 0.5 | D9: =1 -> 1 | E9: =1 -> 1 | F9: =1 -> 1 | G9: =1 -> 1
A10: Upgrades: share still owed at year end | C10: =MAX(0,((1+Assumptions!$B$26)^Assumptions!$B$27-(1+Assumptions!$B$26)^C6)/((1+Assumptions!$B$26)^Assumptions!$B$27-1)) -> 0.6874243 | D10: =MAX(0,((1+Assumptions!$B$26)^Assumptions!$B$27-(1+Assumptions!$B$26)^D6)/((1+Assumptions!$B$26)^Assumptions!$B$27-1)) -> 0.35453118 | E10: =MAX(0,((1+Assumptions!$B$26)^Assumptions!$B$27-(1+Assumptions!$B$26)^E6)/((1+Assumptions!$B$26)^Assumptions!$B$27-1)) -> 0 | F10: =MAX(0,((1+Assumptions!$B$26)^Assumptions!$B$27-(1+Assumptions!$B$26)^F6)/((1+Assumptions!$B$26)^Assumptions!$B$27-1)) -> 0 | G10: =MAX(0,((1+Assumptions!$B$26)^Assumptions!$B$27-(1+Assumptions!$B$26)^G6)/((1+Assumptions!$B$26)^Assumptions!$B$27-1)) -> 0
A11: Upgrades: average share still invested | C11: =0.5 -> 0.5 | D11: =(1+C10)/2 -> 0.84371215 | E11: =(C10+D10)/2 -> 0.52097774 | F11: =(D10+E10)/2 -> 0.17726559 | G11: =(E10+F10)/2 -> 0
A12: Upgrades: share of year a shop is repaying | C12: =0.5 -> 0.5 | D12: =1 -> 1 | E12: =1 -> 1 | F12: =0.5 -> 0.5 | G12: =0 -> 0
A13: EV: average share still invested (paid back evenly over the EV payback period) | C13: =0.5*(1+(1-0.5/Assumptions!$B$137))/2 -> 0.48214286 | D13: =MAX(0,1-1/Assumptions!$B$137) -> 0.85714286 | E13: =MAX(0,1-2/Assumptions!$B$137) -> 0.71428571 | F13: =MAX(0,1-3/Assumptions!$B$137) -> 0.57142857 | G13: =MAX(0,1-4/Assumptions!$B$137) -> 0.42857143
A14: EV: share of money paid back in the year | C14: =0.5/Assumptions!$B$137 -> 0.071428571 | D14: =IF(2-0.5<=Assumptions!$B$137,1/Assumptions!$B$137,0) -> 0.14285714 | E14: =IF(3-0.5<=Assumptions!$B$137,1/Assumptions!$B$137,0) -> 0.14285714 | F14: =IF(4-0.5<=Assumptions!$B$137,1/Assumptions!$B$137,0) -> 0.14285714 | G14: =IF(5-0.5<=Assumptions!$B$137,1/Assumptions!$B$137,0) -> 0.14285714
A15: Pool 1 – Rooftop solar
A16: New solar capacity with resident share | B16: MW | C16: =Yearly_Inputs!$B$5 -> 3 | D16: =Yearly_Inputs!$C$5 -> 3 | E16: =Yearly_Inputs!$D$5 -> 4 | F16: =Yearly_Inputs!$E$5 -> 5 | G16: =Yearly_Inputs!$F$5 -> 5
A17: Money raised from residents | B17: RM | C17: =C16*1000*Assumptions!$B$16*Assumptions!$B$18 -> 2880000 | D17: =D16*1000*Assumptions!$B$16*Assumptions!$B$18 -> 2880000 | E17: =E16*1000*Assumptions!$B$16*Assumptions!$B$18 -> 3840000 | F17: =F16*1000*Assumptions!$B$16*Assumptions!$B$18 -> 4800000 | G17: =G16*1000*Assumptions!$B$16*Assumptions!$B$18 -> 4800000
A18: Residents' money still invested (average) | B18: RM | C18: =C17*C8 -> 1440000 | D18: =C17*D8+D17*C8 -> 4059396.3 | E18: =C17*E8+D17*D8+E17*C8 -> 6624555 | F18: =C17*F8+D17*E8+E17*D8+F17*C8 -> 9501896.3 | G18: =C17*G8+D17*F8+E17*E8+F17*D8+G17*C8 -> 12005294
A19: Yearly payment per RM1 raised | B19: factor | C19: =PMT(Assumptions!$B$19,Assumptions!$B$20,-1) -> 0.2309748 | D19: =PMT(Assumptions!$B$19,Assumptions!$B$20,-1) -> 0.2309748 | E19: =PMT(Assumptions!$B$19,Assumptions!$B$20,-1) -> 0.2309748 | F19: =PMT(Assumptions!$B$19,Assumptions!$B$20,-1) -> 0.2309748 | G19: =PMT(Assumptions!$B$19,Assumptions!$B$20,-1) -> 0.2309748
A20: Payouts to residents | B20: RM | C20: =(C17*C9)*C19 -> 332603.71 | D20: =(C17*D9+D17*C9)*D19 -> 997811.13 | E20: =(C17*E9+D17*D9+E17*C9)*E19 -> 1773886.4 | F20: =(C17*F9+D17*E9+E17*D9+F17*C9)*F19 -> 2771697.6 | G20: =(C17*G9+D17*F9+E17*E9+F17*D9+G17*C9)*G19 -> 3880376.6
A21: Solar capacity running (average) | B21: MW | C21: =C16*C9 -> 1.5 | D21: =C16*D9+D16*C9 -> 4.5 | E21: =C16*E9+D16*D9+E16*C9 -> 8 | F21: =C16*F9+D16*E9+E16*D9+F16*C9 -> 12.5 | G21: =C16*G9+D16*F9+E16*E9+F16*D9+G16*C9 -> 17.5
A22: Solar power produced | B22: MWh | C22: =C21*Assumptions!$B$17 -> 1875 | D22: =D21*Assumptions!$B$17 -> 5625 | E22: =E21*Assumptions!$B$17 -> 10000 | F22: =F21*Assumptions!$B$17 -> 15625 | G22: =G21*Assumptions!$B$17 -> 21875
A23: CO2 avoided by solar | B23: tCO2e | C23: =C22*Assumptions!$B$12 -> 1387.5 | D23: =D22*Assumptions!$B$12 -> 4162.5 | E23: =E22*Assumptions!$B$12 -> 7400 | F23: =F22*Assumptions!$B$12 -> 11562.5 | G23: =G22*Assumptions!$B$12 -> 16187.5
A24: Pool 2 – Shop energy upgrades
A25: New shops upgraded | B25: shops | C25: =Yearly_Inputs!$B$6 -> 15 | D25: =Yearly_Inputs!$C$6 -> 25 | E25: =Yearly_Inputs!$D$6 -> 10 | F25: =Yearly_Inputs!$E$6 -> 10 | G25: =Yearly_Inputs!$F$6 -> 10
A26: Money raised from residents | B26: RM | C26: =C25*Assumptions!$B$23 -> 300000 | D26: =D25*Assumptions!$B$23 -> 500000 | E26: =E25*Assumptions!$B$23 -> 200000 | F26: =F25*Assumptions!$B$23 -> 200000 | G26: =G25*Assumptions!$B$23 -> 200000
A27: Residents' money still invested (average) | B27: RM | C27: =C26*C11 -> 150000 | D27: =C26*D11+D26*C11 -> 503113.64 | E27: =C26*E11+D26*D11+E26*C11 -> 678149.4 | F27: =C26*F11+D26*E11+E26*D11+F26*C11 -> 582410.97 | G27: =C26*G11+D26*F11+E26*E11+F26*D11+G26*C11 -> 461570.77
A28: Shops repaying (shop-years) | B28: shop-yrs | C28: =C25*C12 -> 7.5 | D28: =C25*D12+D25*C12 -> 27.5 | E28: =C25*E12+D25*D12+E25*C12 -> 45 | F28: =C25*F12+D25*E12+E25*D12+F25*C12 -> 47.5 | G28: =C25*G12+D25*F12+E25*E12+F25*D12+G25*C12 -> 37.5
A29: Yearly payout per shop to residents | B29: RM | C29: =PMT(Assumptions!$B$26/12,Assumptions!$B$27*12,-Assumptions!$B$23)*12 -> 7355.7607 | D29: =PMT(Assumptions!$B$26/12,Assumptions!$B$27*12,-Assumptions!$B$23)*12 -> 7355.7607 | E29: =PMT(Assumptions!$B$26/12,Assumptions!$B$27*12,-Assumptions!$B$23)*12 -> 7355.7607 | F29: =PMT(Assumptions!$B$26/12,Assumptions!$B$27*12,-Assumptions!$B$23)*12 -> 7355.7607 | G29: =PMT(Assumptions!$B$26/12,Assumptions!$B$27*12,-Assumptions!$B$23)*12 -> 7355.7607
A30: Payouts to residents | B30: RM | C30: =C28*C29 -> 55168.205 | D30: =D28*D29 -> 202283.42 | E30: =E28*E29 -> 331009.23 | F30: =F28*F29 -> 349398.63 | G30: =G28*G29 -> 275841.03
A31: Safety margin per shop-year (repayment counted − payout) | B31: RM | C31: =C56*12-C29 -> 2244.2393 | D31: =D56*12-D29 -> 2244.2393 | E31: =E56*12-E29 -> 2244.2393 | F31: =F56*12-F29 -> 2244.2393 | G31: =G56*12-G29 -> 2244.2393
A32: Savings shops keep | B32: RM | C32: =C28*Assumptions!$B$24*12*(1-Assumptions!$B$25) -> 18000 | D32: =D28*Assumptions!$B$24*12*(1-Assumptions!$B$25) -> 66000 | E32: =E28*Assumptions!$B$24*12*(1-Assumptions!$B$25) -> 108000 | F32: =F28*Assumptions!$B$24*12*(1-Assumptions!$B$25) -> 114000 | G32: =G28*Assumptions!$B$24*12*(1-Assumptions!$B$25) -> 90000
A33: Electricity saved | B33: MWh | C33: =C28*Assumptions!$B$24*12/Assumptions!$B$11/1000 -> 198.23789 | D33: =D28*Assumptions!$B$24*12/Assumptions!$B$11/1000 -> 726.87225 | E33: =E28*Assumptions!$B$24*12/Assumptions!$B$11/1000 -> 1189.4273 | F33: =F28*Assumptions!$B$24*12/Assumptions!$B$11/1000 -> 1255.5066 | G33: =G28*Assumptions!$B$24*12/Assumptions!$B$11/1000 -> 991.18943
A34: CO2 avoided by upgrades | B34: tCO2e | C34: =C33*Assumptions!$B$12 -> 146.69604 | D34: =D33*Assumptions!$B$12 -> 537.88546 | E34: =E33*Assumptions!$B$12 -> 880.17621 | F34: =F33*Assumptions!$B$12 -> 929.07489 | G34: =G33*Assumptions!$B$12 -> 733.48018
A35: Pool 3 – EV charging
A36: New EV chargers | B36: chargers | C36: =Yearly_Inputs!$B$7 -> 1 | D36: =Yearly_Inputs!$C$7 -> 2 | E36: =Yearly_Inputs!$D$7 -> 2 | F36: =Yearly_Inputs!$E$7 -> 2 | G36: =Yearly_Inputs!$F$7 -> 2
A37: Money raised from residents (net cost after grant × residents' share) | B37: RM | C37: =C36*EV_Pilot!$B$46*Assumptions!$B$31 -> 22500 | D37: =D36*EV_Pilot!$B$46*Assumptions!$B$31 -> 45000 | E37: =E36*EV_Pilot!$B$46*Assumptions!$B$31 -> 45000 | F37: =F36*EV_Pilot!$B$46*Assumptions!$B$31 -> 45000 | G37: =G36*EV_Pilot!$B$46*Assumptions!$B$31 -> 45000
A38: Residents' money still invested (average) | B38: RM | C38: =C37*C13 -> 10848.214 | D38: =C37*D13+D37*C13 -> 40982.143 | E38: =C37*E13+D37*D13+E37*C13 -> 76339.286 | F38: =C37*F13+D37*E13+E37*D13+F37*C13 -> 105267.86 | G38: =C37*G13+D37*F13+E37*E13+F37*D13+G37*C13 -> 127767.86
A39: Chargers running (charger-years) | B39: chg-yrs | C39: =C36*C9 -> 0.5 | D39: =C36*D9+D36*C9 -> 2 | E39: =C36*E9+D36*D9+E36*C9 -> 4 | F39: =C36*F9+D36*E9+E36*D9+F36*C9 -> 6 | G39: =C36*G9+D36*F9+E36*E9+F36*D9+G36*C9 -> 8
A40: Net charging profit per charger-year (blended DC/AC, from EV_Pilot) | B40: RM | C40: =EV_Pilot!$B$50 -> 8979.74 | D40: =EV_Pilot!$B$50 -> 8979.74 | E40: =EV_Pilot!$B$50 -> 8979.74 | F40: =EV_Pilot!$B$50 -> 8979.74 | G40: =EV_Pilot!$B$50 -> 8979.74
A41: Residents' share of charging profit (their 50%, before the 70/10/10/10 split) | B41: RM | C41: =C39*EV_Pilot!$B$54 -> 2244.935 | D41: =D39*EV_Pilot!$B$54 -> 8979.74 | E41: =E39*EV_Pilot!$B$54 -> 17959.48 | F41: =F39*EV_Pilot!$B$54 -> 26939.22 | G41: =G39*EV_Pilot!$B$54 -> 35918.96
...

Sheet EV_Pilot
A1: EV_Pilot – one charger's economics, who gets the money, and stress tests
A2: Each column is a case. B = normal, C = conservative (all stresses together, from Scenarios). D–K change ONE thing from normal. L and M switch off a protection. Every cell is a formula.
A4: Item | B4: Normal | C4: Conservative (all stresses) | D4: Tariff +20% | E4: Maintenance +50% | F4: Downtime 10% | G4: Price −20% | H4: Grant not approved | I4: Usage 30 kWh/day | J4: No idle or membership fees | K4: Mall MV demand charge | L4: Normal, no deferral (70% split from day 1) | M4: Conservative, no top-up | N4: Unit / how
A5: Usage and prices
A6: Charging sessions per charger per day | B6: =Assumptions!$B$105 -> 2 | C6: =Scenarios!$C$15 -> 1.5 | D6: =Assumptions!$B$105 -> 2 | E6: =Assumptions!$B$105 -> 2 | F6: =Assumptions!$B$105 -> 2 | G6: =Assumptions!$B$105 -> 2 | H6: =Assumptions!$B$105 -> 2 | I6: =Scenarios!$C$15 -> 1.5 | J6: =Assumptions!$B$105 -> 2 | K6: =Assumptions!$B$105 -> 2 | L6: =Assumptions!$B$105 -> 2 | M6: =Scenarios!$C$15 -> 1.5 | N6: sessions
A7: Energy per session | B7: =Assumptions!$B$106 -> 30 | C7: =Scenarios!$C$16 -> 20 | D7: =Assumptions!$B$106 -> 30 | E7: =Assumptions!$B$106 -> 30 | F7: =Assumptions!$B$106 -> 30 | G7: =Assumptions!$B$106 -> 30 | H7: =Assumptions!$B$106 -> 30 | I7: =Scenarios!$C$16 -> 20 | J7: =Assumptions!$B$106 -> 30 | K7: =Assumptions!$B$106 -> 30 | L7: =Assumptions!$B$106 -> 30 | M7: =Scenarios!$C$16 -> 20 | N7: kWh
A8: Downtime | B8: =0 -> 0 | C8: =Scenarios!$C$19 -> 0.1 | D8: =0 -> 0 | E8: =0 -> 0 | F8: =Scenarios!$C$19 -> 0.1 | G8: =0 -> 0 | H8: =0 -> 0 | I8: =0 -> 0 | J8: =0 -> 0 | K8: =0 -> 0 | L8: =0 -> 0 | M8: =Scenarios!$C$19 -> 0.1 | N8: % of time
A9: Energy sold per charger per day | B9: =B6*B7*(1-B8) -> 60 | C9: =C6*C7*(1-C8) -> 27 | D9: =D6*D7*(1-D8) -> 60 | E9: =E6*E7*(1-E8) -> 60 | F9: =F6*F7*(1-F8) -> 54 | G9: =G6*G7*(1-G8) -> 60 | H9: =H6*H7*(1-H8) -> 60 | I9: =I6*I7*(1-I8) -> 30 | ... M9: =M6*M7*(1-M8) -> 27 | N9: kWh/day
A10: Price level (1 − competitor price drop) | B10: =1-0 -> 1 | C10: =1-Scenarios!$C$11 -> 0.8 | D10: =1-0 -> 1 | E10: =1-0 -> 1 | F10: =1-0 -> 1 | G10: =1-Scenarios!$C$11 -> 0.8 | H10: =1-0 -> 1 | I10: =1-0 -> 1 | J10: =1-0 -> 1 | K10: =1-0 -> 1 | L10: =1-0 -> 1 | M10: =1-Scenarios!$C$11 -> 0.8
A11: DC average price (standard + peak) | B11: =(Assumptions!$B$32*(1-Assumptions!$B$120)+Assumptions!$B$119*Assumptions!$B$120)*B10 -> 1.49 | C11: =(Assumptions!$B$32*(1-Assumptions!$B$120)+Assumptions!$B$119*Assumptions!$B$120)*C10 -> 1.192 | D11: =(Assumptions!$B$32*(1-Assumptions!$B$120)+Assumptions!$B$119*Assumptions!$B$120)*D10 -> 1.49 | E11: =(Assumptions!$B$32*(1-Assumptions!$B$120)+Assumptions!$B$119*Assumptions!$B$120)*E10 -> 1.49 | F11: =(Assumptions!$B$32*(1-Assumptions!$B$120)+Assumptions!$B$119*Assumptions!$B$120)*F10 -> 1.49 | G11: =(Assumptions!$B$32*(1-Assumptions!$B$120)+Assumptions!$B$119*Assumptions!$B$120)*G10 -> 1.192 | H11: =(Assumptions!$B$32*(1-Assumptions!$B$120)+Assumptions!$B$119*Assumptions!$B$120)*H10 -> 1.49 | I11: =(Assumptions!$B$32*(1-Assumptions!$B$120)+Assumptions!$B$119*Assumptions!$B$120)*I10 -> 1.49 | ... M11: =(Assumptions!$B$32*(1-Assumptions!$B$120)+Assumptions!$B$119*Assumptions!$B$120)*M10 -> 1.192 | N11: RM/kWh
A12: AC average price (standard + off-peak) | B12: =(Assumptions!$B$118*(1-Assumptions!$B$122)+Assumptions!$B$121*Assumptions!$B$122)*B10 -> 0.95 | C12: =(Assumptions!$B$118*(1-Assumptions!$B$122)+Assumptions!$B$121*Assumptions!$B$122)*C10 -> 0.76 | D12: =(Assumptions!$B$118*(1-Assumptions!$B$122)+Assumptions!$B$121*Assumptions!$B$122)*D10 -> 0.95 | E12: =(Assumptions!$B$118*(1-Assumptions!$B$122)+Assumptions!$B$121*Assumptions!$B$122)*E10 -> 0.95 | F12: =(Assumptions!$B$118*(1-Assumptions!$B$122)+Assumptions!$B$121*Assumptions!$B$122)*F10 -> 0.95 | G12: =(Assumptions!$B$118*(1-Assumptions!$B$122)+Assumptions!$B$121*Assumptions!$B$122)*G10 -> 0.76 | H12: =(Assumptions!$B$118*(1-Assumptions!$B$122)+Assumptions!$B$121*Assumptions!$B$122)*H10 -> 0.95 | I12: =(Assumptions!$B$118*(1-Assumptions!$B$122)+Assumptions!$B$121*Assumptions!$B$122)*I10 -> 0.95 | ... M12: =(Assumptions!$B$118*(1-Assumptions!$B$122)+Assumptions!$B$121*Assumptions!$B$122)*M10 -> 0.76 | N12: RM/kWh
A13: Electricity cost per kWh (energy + capacity + network) | B13: =Assumptions!$B$102*(1+0) -> 0.5068 | C13: =Assumptions!$B$102*(1+Scenarios!$C$17) -> 0.60816 | D13: =Assumptions!$B$102*(1+Scenarios!$C$17) -> 0.60816 | E13: =Assumptions!$B$102*(1+0) -> 0.5068 | F13: =Assumptions!$B$102*(1+0) -> 0.5068 | G13: =Assumptions!$B$102*(1+0) -> 0.5068 | H13: =Assumptions!$B$102*(1+0) -> 0.5068 | I13: =Assumptions!$B$102*(1+0) -> 0.5068 | J13: =Assumptions!$B$102*(1+0) -> 0.5068 | K13: =Assumptions!$B$102*(1+0) -> 0.5068 | L13: =Assumptions!$B$102*(1+0) -> 0.5068 | M13: =Assumptions!$B$102*(1+Scenarios!$C$17) -> 0.60816 | N13: RM/kWh
A14: of which capacity charge | B14: =Assumptions!$B$103*(1+0) -> 0.0883 | C14: =Assumptions!$B$103*(1+Scenarios!$C$17) -> 0.10596 | D14: =Assumptions!$B$103*(1+Scenarios!$C$17) -> 0.10596 | E14: =Assumptions!$B$103*(1+0) -> 0.0883 | F14: =Assumptions!$B$103*(1+0) -> 0.0883 | G14: =Assumptions!$B$103*(1+0) -> 0.0883 | H14: =Assumptions!$B$103*(1+0) -> 0.0883 | I14: =Assumptions!$B$103*(1+0) -> 0.0883 | J14: =Assumptions!$B$103*(1+0) -> 0.0883 | K14: =Assumptions!$B$103*(1+0) -> 0.0883 | L14: =Assumptions!$B$103*(1+0) -> 0.0883 | M14: =Assumptions!$B$103*(1+Scenarios!$C$17) -> 0.10596 | N14: RM/kWh
A15: Maximum-demand charge per kW (only if the site is on the MV tariff) | B15: =0*Assumptions!$B$141 -> 0 | C15: =0*Assumptions!$B$141 -> 0 | D15: =0*Assumptions!$B$141 -> 0 | E15: =0*Assumptions!$B$141 -> 0 | F15: =0*Assumptions!$B$141 -> 0 | G15: =0*Assumptions!$B$141 -> 0 | H15: =0*Assumptions!$B$141 -> 0 | I15: =0*Assumptions!$B$141 -> 0 | J15: =0*Assumptions!$B$141 -> 0 | K15: =1*Assumptions!$B$141 -> 89.27 | L15: =0*Assumptions!$B$141 -> 0 | M15: =0*Assumptions!$B$141 -> 0 | N15: RM/kW/month
A16: DC 60 kW charger (per year)
A17: Installed cost | B17: =Assumptions!$B$116 -> 100000 | C17: =Assumptions!$B$116 -> 100000 | D17: =Assumptions!$B$116 -> 100000 | E17: =Assumptions!$B$116 -> 100000 | F17: =Assumptions!$B$116 -> 100000 | G17: =Assumptions!$B$116 -> 100000 | H17: =Assumptions!$B$116 -> 100000 | I17: =Assumptions!$B$116 -> 100000 | ... M17: =Assumptions!$B$116 -> 100000 | N17: RM
A18: MARii grant (if approved) | B18: =MIN(Assumptions!$B$116*Assumptions!$B$104,Assumptions!$B$129)*1 -> 50000 | C18: =MIN(Assumptions!$B$116*Assumptions!$B$104,Assumptions!$B$129)*Scenarios!$C$20 -> 0 | D18: =MIN(Assumptions!$B$116*Assumptions!$B$104,Assumptions!$B$129)*1 -> 50000 | E18: =MIN(Assumptions!$B$116*Assumptions!$B$104,Assumptions!$B$129)*1 -> 50000 | F18: =MIN(Assumptions!$B$116*Assumptions!$B$104,Assumptions!$B$129)*1 -> 50000 | G18: =MIN(Assumptions!$B$116*Assumptions!$B$104,Assumptions!$B$129)*1 -> 50000 | H18: =MIN(Assumptions!$B$116*Assumptions!$B$104,Assumptions!$B$129)*Scenarios!$C$20 -> 0 | I18: =MIN(Assumptions!$B$116*Assumptions!$B$104,Assumptions!$B$129)*1 -> 50000 | J18: =MIN(Assumptions!$B$116*Assumptions!$B$104,Assumptions!$B$129)*1 -> 50000 | K18: =MIN(Assumptions!$B$116*Assumptions!$B$104,Assumptions!$B$129)*1 -> 50000 | L18: =MIN(Assumptions!$B$116*Assumptions!$B$104,Assumptions!$B$129)*1 -> 50000 | M18: =MIN(Assumptions!$B$116*Assumptions!$B$104,Assumptions!$B$129)*Scenarios!$C$20 -> 0 | N18: RM
A19: Compliance cost share (per site ÷ chargers per site) | B19: =Assumptions!$B$107/Assumptions!$B$128 -> 7500 | C19: =Assumptions!$B$107/Assumptions!$B$128 -> 7500 | D19: =Assumptions!$B$107/Assumptions!$B$128 -> 7500 | E19: =Assumptions!$B$107/Assumptions!$B$128 -> 7500 | F19: =Assumptions!$B$107/Assumptions!$B$128 -> 7500 | G19: =Assumptions!$B$107/Assumptions!$B$128 -> 7500 | H19: =Assumptions!$B$107/Assumptions!$B$128 -> 7500 | I19: =Assumptions!$B$107/Assumptions!$B$128 -> 7500 | ... M19: =Assumptions!$B$107/Assumptions!$B$128 -> 7500 | N19: RM
A20: Net installed cost | B20: =B17-B18+B19 -> 57500 | C20: =C17-C18+C19 -> 107500 | D20: =D17-D18+D19 -> 57500 | E20: =E17-E18+E19 -> 57500 | F20: =F17-F18+F19 -> 57500 | G20: =G17-G18+G19 -> 57500 | H20: =H17-H18+H19 -> 107500 | I20: =I17-I18+I19 -> 57500 | ... M20: =M17-M18+M19 -> 107500 | N20: RM
A21: Charging revenue | B21: =365*B9*B11 -> 32631 | C21: =365*C9*C11 -> 11747.16 | D21: =365*D9*D11 -> 32631 | E21: =365*E9*E11 -> 32631 | F21: =365*F9*F11 -> 29367.9 | G21: =365*G9*G11 -> 26104.8 | H21: =365*H9*H11 -> 32631 | I21: =365*I9*I11 -> 16315.5 | ... M21: =365*M9*M11 -> 11747.16 | N21: RM/yr
A22: Idle (occupancy) fees | B22: =365*Assumptions!$B$124*Assumptions!$B$123*(1-B8) -> 1460 | C22: =365*Scenarios!$C$21*Assumptions!$B$123*(1-C8) -> 657 | D22: =365*Assumptions!$B$124*Assumptions!$B$123*(1-D8) -> 1460 | E22: =365*Assumptions!$B$124*Assumptions!$B$123*(1-E8) -> 1460 | F22: =365*Assumptions!$B$124*Assumptions!$B$123*(1-F8) -> 1314 | G22: =365*Assumptions!$B$124*Assumptions!$B$123*(1-G8) -> 1460 | H22: =365*Assumptions!$B$124*Assumptions!$B$123*(1-H8) -> 1460 | I22: =365*Assumptions!$B$124*Assumptions!$B$123*(1-I8) -> 1460 | J22: =365*0*Assumptions!$B$123*(1-J8) -> 0 | K22: =365*Assumptions!$B$124*Assumptions!$B$123*(1-K8) -> 1460 | L22: =365*Assumptions!$B$124*Assumptions!$B$123*(1-L8) -> 1460 | M22: =365*Scenarios!$C$21*Assumptions!$B$123*(1-M8) -> 657 | N22: RM/yr
A23: Membership fees | B23: =Assumptions!$B$126*Assumptions!$B$125*12 -> 1800 | C23: =Scenarios!$C$22*Assumptions!$B$125*12 -> 900 | D23: =Assumptions!$B$126*Assumptions!$B$125*12 -> 1800 | E23: =Assumptions!$B$126*Assumptions!$B$125*12 -> 1800 | F23: =Assumptions!$B$126*Assumptions!$B$125*12 -> 1800 | G23: =Assumptions!$B$126*Assumptions!$B$125*12 -> 1800 | H23: =Assumptions!$B$126*Assumptions!$B$125*12 -> 1800 | I23: =Assumptions!$B$126*Assumptions!$B$125*12 -> 1800 | J23: =0*Assumptions!$B$125*12 -> 0 | K23: =Assumptions!$B$126*Assumptions!$B$125*12 -> 1800 | L23: =Assumptions!$B$126*Assumptions!$B$125*12 -> 1800 | M23: =Scenarios!$C$22*Assumptions!$B$125*12 -> 900 | N23: RM/yr
A24: Payment and app costs | B24: =-Assumptions!$B$33*(B21+B22+B23) -> -1076.73 | C24: =-Assumptions!$B$33*(C21+C22+C23) -> -399.1248 | D24: =-Assumptions!$B$33*(D21+D22+D23) -> -1076.73 | E24: =-Assumptions!$B$33*(E21+E22+E23) -> -1076.73 | F24: =-Assumptions!$B$33*(F21+F22+F23) -> -974.457 | G24: =-Assumptions!$B$33*(G21+G22+G23) -> -880.944 | H24: =-Assumptions!$B$33*(H21+H22+H23) -> -1076.73 | I24: =-Assumptions!$B$33*(I21+I22+I23) -> -587.265 | ... M24: =-Assumptions!$B$33*(M21+M22+M23) -> -399.1248 | N24: RM/yr
A25: Electricity (incl. capacity and network charges) | B25: =-365*B9*B13 -> -11098.92 | C25: =-365*C9*C13 -> -5993.4168 | D25: =-365*D9*D13 -> -13318.704 | E25: =-365*E9*E13 -> -11098.92 | F25: =-365*F9*F13 -> -9989.028 | G25: =-365*G9*G13 -> -11098.92 | H25: =-365*H9*H13 -> -11098.92 | I25: =-365*I9*I13 -> -5549.46 | ... M25: =-365*M9*M13 -> -5993.4168 | N25: RM/yr
A26: Maximum-demand charge (MV sites only) | B26: =-B15*Assumptions!$B$142*1*12 -> 0 | C26: =-C15*Assumptions!$B$142*1*12 -> 0 | D26: =-D15*Assumptions!$B$142*1*12 -> 0 | E26: =-E15*Assumptions!$B$142*1*12 -> 0 | F26: =-F15*Assumptions!$B$142*1*12 -> 0 | G26: =-G15*Assumptions!$B$142*1*12 -> 0 | H26: =-H15*Assumptions!$B$142*1*12 -> 0 | I26: =-I15*Assumptions!$B$142*1*12 -> 0 | ... M26: =-M15*Assumptions!$B$142*1*12 -> 0 | N26: RM/yr
A27: Maintenance and CPO service fee | B27: =-Assumptions!$B$34*(1+0) -> -10000 | C27: =-Assumptions!$B$34*(1+Scenarios!$C$18) -> -15000 | D27: =-Assumptions!$B$34*(1+0) -> -10000 | E27: =-Assumptions!$B$34*(1+Scenarios!$C$18) -> -15000 | F27: =-Assumptions!$B$34*(1+0) -> -10000 | G27: =-Assumptions!$B$34*(1+0) -> -10000 | H27: =-Assumptions!$B$34*(1+0) -> -10000 | I27: =-Assumptions!$B$34*(1+0) -> -10000 | J27: =-Assumptions!$B$34*(1+0) -> -10000 | K27: =-Assumptions!$B$34*(1+0) -> -10000 | L27: =-Assumptions!$B$34*(1+0) -> -10000 | M27: =-Assumptions!$B$34*(1+Scenarios!$C$18) -> -15000 | N27: RM/yr
A28: Compliance audit share | B28: =-Assumptions!$B$108/Assumptions!$B$128 -> -2500 | C28: =-Assumptions!$B$108/Assumptions!$B$128 -> -2500 | D28: =-Assumptions!$B$108/Assumptions!$B$128 -> -2500 | E28: =-Assumptions!$B$108/Assumptions!$B$128 -> -2500 | F28: =-Assumptions!$B$108/Assumptions!$B$128 -> -2500 | G28: =-Assumptions!$B$108/Assumptions!$B$128 -> -2500 | H28: =-Assumptions!$B$108/Assumptions!$B$128 -> -2500 | I28: =-Assumptions!$B$108/Assumptions!$B$128 -> -2500 | ... M28: =-Assumptions!$B$108/Assumptions!$B$128 -> -2500 | N28: RM/yr
A29: Net charging profit | B29: =SUM(B21:B28) -> 11215.35 | C29: =SUM(C21:C28) -> -10588.382 | D29: =SUM(D21:D28) -> 8995.566 | E29: =SUM(E21:E28) -> 6215.35 | F29: =SUM(F21:F28) -> 9018.415 | G29: =SUM(G21:G28) -> 4884.936 | H29: =SUM(H21:H28) -> 11215.35 | I29: =SUM(I21:I28) -> 938.775 | ... M29: =SUM(M21:M28) -> -10588.382 | N29: RM/yr
A30: Revenue per charger per day | B30: =(B21+B22+B23)/365 -> 98.331507 | C30: =(C21+C22+C23)/365 -> 36.449753 | D30: =(D21+D22+D23)/365 -> 98.331507 | E30: =(E21+E22+E23)/365 -> 98.331507 | F30: =(F21+F22+F23)/365 -> 88.991507 | G30: =(G21+G22+G23)/365 -> 80.451507 | H30: =(H21+H22+H23)/365 -> 98.331507 | I30: =(I21+I22+I23)/365 -> 53.631507 | ... M30: =(M21+M22+M23)/365 -> 36.449753 | N30: RM/day
A31: AC 22 kW charger (per year)
A32: Installed cost | B32: =Assumptions!$B$117 -> 25000 | C32: =Assumptions!$B$117 -> 25000 | D32: =Assumptions!$B$117 -> 25000 | E32: =Assumptions!$B$117 -> 25000 | F32: =Assumptions!$B$117 -> 25000 | G32: =Assumptions!$B$117 -> 25000 | H32: =Assumptions!$B$117 -> 25000 | I32: =Assumptions!$B$117 -> 25000 | ... M32: =Assumptions!$B$117 -> 25000 | N32: RM
A33: Compliance cost share (per site ÷ chargers per site) | B33: =Assumptions!$B$107/Assumptions!$B$128 -> 7500 | C33: =Assumptions!$B$107/Assumptions!$B$128 -> 7500 | D33: =Assumptions!$B$107/Assumptions!$B$128 -> 7500 | E33: =Assumptions!$B$107/Assumptions!$B$128 -> 7500 | F33: =Assumptions!$B$107/Assumptions!$B$128 -> 7500 | G33: =Assumptions!$B$107/Assumptions!$B$128 -> 7500 | H33: =Assumptions!$B$107/Assumptions!$B$128 -> 7500 | I33: =Assumptions!$B$107/Assumptions!$B$128 -> 7500 | ... M33: =Assumptions!$B$107/Assumptions!$B$128 -> 7500 | N33: RM
A34: Net installed cost | B34: =B32+B33 -> 32500 | C34: =C32+C33 -> 32500 | D34: =D32+D33 -> 32500 | E34: =E32+E33 -> 32500 | F34: =F32+F33 -> 32500 | G34: =G32+G33 -> 32500 | H34: =H32+H33 -> 32500 | I34: =I32+I33 -> 32500 | ... M34: =M32+M33 -> 32500 | N34: RM
A35: Charging revenue | B35: =365*B9*B12 -> 20805 | C35: =365*C9*C12 -> 7489.8 | D35: =365*D9*D12 -> 20805 | E35: =365*E9*E12 -> 20805 | F35: =365*F9*F12 -> 18724.5 | G35: =365*G9*G12 -> 16644 | H35: =365*H9*H12 -> 20805 | I35: =365*I9*I12 -> 10402.5 | ... M35: =365*M9*M12 -> 7489.8 | N35: RM/yr
A36: Idle (occupancy) fees | B36: =365*Assumptions!$B$124*Assumptions!$B$123*(1-B8) -> 1460 | C36: =365*Scenarios!$C$21*Assumptions!$B$123*(1-C8) -> 657 | D36: =365*Assumptions!$B$124*Assumptions!$B$123*(1-D8) -> 1460 | E36: =365*Assumptions!$B$124*Assumptions!$B$123*(1-E8) -> 1460 | F36: =365*Assumptions!$B$124*Assumptions!$B$123*(1-F8) -> 1314 | G36: =365*Assumptions!$B$124*Assumptions!$B$123*(1-G8) -> 1460 | H36: =365*Assumptions!$B$124*Assumptions!$B$123*(1-H8) -> 1460 | I36: =365*Assumptions!$B$124*Assumptions!$B$123*(1-I8) -> 1460 | J36: =365*0*Assumptions!$B$123*(1-J8) -> 0 | K36: =365*Assumptions!$B$124*Assumptions!$B$123*(1-K8) -> 1460 | L36: =365*Assumptions!$B$124*Assumptions!$B$123*(1-L8) -> 1460 | M36: =365*Scenarios!$C$21*Assumptions!$B$123*(1-M8) -> 657 | N36: RM/yr
A37: Membership fees | B37: =Assumptions!$B$126*Assumptions!$B$125*12 -> 1800 | C37: =Scenarios!$C$22*Assumptions!$B$125*12 -> 900 | D37: =Assumptions!$B$126*Assumptions!$B$125*12 -> 1800 | E37: =Assumptions!$B$126*Assumptions!$B$125*12 -> 1800 | F37: =Assumptions!$B$126*Assumptions!$B$125*12 -> 1800 | G37: =Assumptions!$B$126*Assumptions!$B$125*12 -> 1800 | H37: =Assumptions!$B$126*Assumptions!$B$125*12 -> 1800 | I37: =Assumptions!$B$126*Assumptions!$B$125*12 -> 1800 | J37: =0*Assumptions!$B$125*12 -> 0 | K37: =Assumptions!$B$126*Assumptions!$B$125*12 -> 1800 | L37: =Assumptions!$B$126*Assumptions!$B$125*12 -> 1800 | M37: =Scenarios!$C$22*Assumptions!$B$125*12 -> 900 | N37: RM/yr
A38: Payment and app costs | B38: =-Assumptions!$B$33*(B35+B36+B37) -> -721.95 | C38: =-Assumptions!$B$33*(C35+C36+C37) -> -271.404 | D38: =-Assumptions!$B$33*(D35+D36+D37) -> -721.95 | E38: =-Assumptions!$B$33*(E35+E36+E37) -> -721.95 | F38: =-Assumptions!$B$33*(F35+F36+F37) -> -655.155 | G38: =-Assumptions!$B$33*(G35+G36+G37) -> -597.12 | H38: =-Assumptions!$B$33*(H35+H36+H37) -> -721.95 | I38: =-Assumptions!$B$33*(I35+I36+I37) -> -409.875 | ... M38: =-Assumptions!$B$33*(M35+M36+M37) -> -271.404 | N38: RM/yr
A39: Electricity (incl. capacity and network charges) | B39: =-365*B9*B13 -> -11098.92 | C39: =-365*C9*C13 -> -5993.4168 | D39: =-365*D9*D13 -> -13318.704 | E39: =-365*E9*E13 -> -11098.92 | F39: =-365*F9*F13 -> -9989.028 | G39: =-365*G9*G13 -> -11098.92 | H39: =-365*H9*H13 -> -11098.92 | I39: =-365*I9*I13 -> -5549.46 | ... M39: =-365*M9*M13 -> -5993.4168 | N39: RM/yr
A40: Maximum-demand charge (MV sites only) | B40: =-B15*Assumptions!$B$142*22/60*12 -> 0 | C40: =-C15*Assumptions!$B$142*22/60*12 -> 0 | D40: =-D15*Assumptions!$B$142*22/60*12 -> 0 | E40: =-E15*Assumptions!$B$142*22/60*12 -> 0 | F40: =-F15*Assumptions!$B$142*22/60*12 -> 0 | G40: =-G15*Assumptions!$B$142*22/60*12 -> 0 | H40: =-H15*Assumptions!$B$142*22/60*12 -> 0 | I40: =-I15*Assumptions!$B$142*22/60*12 -> 0 | ... M40: =-M15*Assumptions!$B$142*22/60*12 -> 0 | N40: RM/yr
A41: Maintenance and CPO service fee | B41: =-Assumptions!$B$127*(1+0) -> -3000 | C41: =-Assumptions!$B$127*(1+Scenarios!$C$18) -> -4500 | D41: =-Assumptions!$B$127*(1+0) -> -3000 | E41: =-Assumptions!$B$127*(1+Scenarios!$C$18) -> -4500 | F41: =-Assumptions!$B$127*(1+0) -> -3000 | G41: =-Assumptions!$B$127*(1+0) -> -3000 | H41: =-Assumptions!$B$127*(1+0) -> -3000 | I41: =-Assumptions!$B$127*(1+0) -> -3000 | J41: =-Assumptions!$B$127*(1+0) -> -3000 | K41: =-Assumptions!$B$127*(1+0) -> -3000 | L41: =-Assumptions!$B$127*(1+0) -> -3000 | M41: =-Assumptions!$B$127*(1+Scenarios!$C$18) -> -4500 | N41: RM/yr
...

Sheet Benefits
A1: 1) Benefits – value created for the developer (customer)
A2: Top: one SDP-size client by its year on the platform. Bottom: all clients together by calendar year.
A4: Benefit | B4: How it is worked out | C4: Year 1 | D4: Year 2 | E4: Year 3 | F4: Year 4 | G4: Year 5
A5: One SDP-size client (by client's year)
A6: A. Cheaper money for solar | B6: Residents' solar money × ((8.5% − 5%) × developer's JV share + JV arrangement fee) | C6: =Pools!C18*((Assumptions!$B$21-Assumptions!$B$19)*Assumptions!$B$14+Assumptions!$B$70) -> 39600 | D6: =Pools!D18*((Assumptions!$B$21-Assumptions!$B$19)*Assumptions!$B$14+Assumptions!$B$70) -> 111633.4 | E6: =Pools!E18*((Assumptions!$B$21-Assumptions!$B$19)*Assumptions!$B$14+Assumptions!$B$70) -> 182175.26 | F6: =Pools!F18*((Assumptions!$B$21-Assumptions!$B$19)*Assumptions!$B$14+Assumptions!$B$70) -> 261302.15 | G6: =Pools!G18*((Assumptions!$B$21-Assumptions!$B$19)*Assumptions!$B$14+Assumptions!$B$70) -> 330145.57
A7: B. Fee from shop upgrades | B7: Shop-years × positive safety margin × developer's share | C7: =Pools!C28*MAX(0,Pools!C31)*Assumptions!$B$28 -> 8415.8974 | D7: =Pools!D28*MAX(0,Pools!D31)*Assumptions!$B$28 -> 30858.291 | E7: =Pools!E28*MAX(0,Pools!E31)*Assumptions!$B$28 -> 50495.384 | F7: =Pools!F28*MAX(0,Pools!F31)*Assumptions!$B$28 -> 53300.684 | G7: =Pools!G28*MAX(0,Pools!G31)*Assumptions!$B$28 -> 42079.487
A8: C. Developer's EV share, less its part of the usage top-up | B8: v3: 10% of residents' EV profit (paid after residents recover) − developer's 33% of any top-up | C8: =Pools!C70-Pools!C71 -> 0 | D8: =Pools!D70-Pools!D71 -> 0 | E8: =Pools!E70-Pools!E71 -> 0 | F8: =Pools!F70-Pools!F71 -> 0 | G8: =Pools!G70-Pools!G71 -> 0
A9: D. Extra mall rent | B9: Money spent at malls × turnover rent | C9: =Pools!C48*Assumptions!$B$10 -> 1286.3148 | D9: =Pools!D48*Assumptions!$B$10 -> 3986.9818 | E9: =Pools!E48*Assumptions!$B$10 -> 6999.4954 | F9: =Pools!F48*Assumptions!$B$10 -> 10379.627 | G9: =Pools!G48*Assumptions!$B$10 -> 13822.198
A10: Cash benefits (A to D, plus F) | C10: =SUM(C6:C9)+C31 -> 53144.65 | D10: =SUM(D6:D9)+D31 -> 158005.98 | E10: =SUM(E6:E9)+E31 -> 260163.14 | F10: =SUM(F6:F9)+F31 -> 357002.77 | G10: =SUM(G6:G9)+G31 -> 430875.69
A11: E. Community-programme saving (actually achieved) | B11: Programme spend × saving rate × share achieved | C11: =Assumptions!$B$13*Yearly_Inputs!$B$8*Assumptions!$B$64 -> 104000 | D11: =Assumptions!$B$13*Yearly_Inputs!$C$8*Assumptions!$B$64 -> 208000 | E11: =Assumptions!$B$13*Yearly_Inputs!$D$8*Assumptions!$B$64 -> 208000 | F11: =Assumptions!$B$13*Yearly_Inputs!$E$8*Assumptions!$B$64 -> 208000 | G11: =Assumptions!$B$13*Yearly_Inputs!$F$8*Assumptions!$B$64 -> 208000
A12: Total benefit for one SDP-size client | C12: =C10+C11 -> 157144.65 | D12: =D10+D11 -> 366005.98 | E12: =E10+E11 -> 468163.14 | F12: =F10+F11 -> 565002.77 | G12: =G10+G11 -> 638875.69
A14: Value to residents and shops (one SDP-size client, not counted in developer ROI)
A15: Residents' profit earned | B15: Payout profit on money invested, after expected shop losses | C15: =Pools!C50 -> 82163.299 | D15: =Pools!D50 -> 237325.4 | E15: =Pools!E50 -> 378613.85 | F15: =Pools!F50 -> 517911.11 | G15: =Pools!G50 -> 636879.55
A16: Savings shops keep | B16: 20% of savings during repayment | C16: =Pools!C32 -> 18000 | D16: =Pools!D32 -> 66000 | E16: =Pools!E32 -> 108000 | F16: =Pools!F32 -> 114000 | G16: =Pools!G32 -> 90000
A17: CO2 avoided (tCO2e) | B17: Solar + upgrades | C17: =Pools!C51 -> 1534.196 | D17: =Pools!D51 -> 4700.3855 | E17: =Pools!E51 -> 8280.1762 | F17: =Pools!F51 -> 12491.575 | G17: =Pools!G51 -> 16920.98
A19: All clients together (by calendar year)
A20: Developer clients on the platform | B20: Cumulative clients signed | C20: =Yearly_Inputs!$B$9 -> 1 | D20: =Yearly_Inputs!$B$9+Yearly_Inputs!$C$9 -> 3 | E20: =Yearly_Inputs!$B$9+Yearly_Inputs!$C$9+Yearly_Inputs!$D$9 -> 5 | F20: =Yearly_Inputs!$B$9+Yearly_Inputs!$C$9+Yearly_Inputs!$D$9+Yearly_Inputs!$E$9 -> 7 | G20: =Yearly_Inputs!$B$9+Yearly_Inputs!$C$9+Yearly_Inputs!$D$9+Yearly_Inputs!$E$9+Yearly_Inputs!$F$9 -> 9
A21: Cash benefits (A to D, plus F), all clients | C21: =Yearly_Inputs!$B$9*Yearly_Inputs!$B$10*C10 -> 53144.65 | D21: =Yearly_Inputs!$B$9*Yearly_Inputs!$B$10*D10+Yearly_Inputs!$C$9*Yearly_Inputs!$C$10*C10 -> 221779.56 | E21: =Yearly_Inputs!$B$9*Yearly_Inputs!$B$10*E10+Yearly_Inputs!$C$9*Yearly_Inputs!$C$10*D10+Yearly_Inputs!$D$9*Yearly_Inputs!$D$10*C10 -> 513543.9 | F21: =Yearly_Inputs!$B$9*Yearly_Inputs!$B$10*F10+Yearly_Inputs!$C$9*Yearly_Inputs!$C$10*E10+Yearly_Inputs!$D$9*Yearly_Inputs!$D$10*D10+Yearly_Inputs!$E$9*Yearly_Inputs!$E$10*C10 -> 922579.3 | G21: =Yearly_Inputs!$B$9*Yearly_Inputs!$B$10*G10+Yearly_Inputs!$C$9*Yearly_Inputs!$C$10*F10+Yearly_Inputs!$D$9*Yearly_Inputs!$D$10*E10+Yearly_Inputs!$E$9*Yearly_Inputs!$E$10*D10+Yearly_Inputs!$F$9*Yearly_Inputs!$F$10*C10 -> 1424855.5
A22: Community-programme saving, all clients | C22: =Yearly_Inputs!$B$9*Yearly_Inputs!$B$10*C11 -> 104000 | D22: =Yearly_Inputs!$B$9*Yearly_Inputs!$B$10*D11+Yearly_Inputs!$C$9*Yearly_Inputs!$C$10*C11 -> 332800 | E22: =Yearly_Inputs!$B$9*Yearly_Inputs!$B$10*E11+Yearly_Inputs!$C$9*Yearly_Inputs!$C$10*D11+Yearly_Inputs!$D$9*Yearly_Inputs!$D$10*C11 -> 582400 | F22: =Yearly_Inputs!$B$9*Yearly_Inputs!$B$10*F11+Yearly_Inputs!$C$9*Yearly_Inputs!$C$10*E11+Yearly_Inputs!$D$9*Yearly_Inputs!$D$10*D11+Yearly_Inputs!$E$9*Yearly_Inputs!$E$10*C11 -> 832000 | G22: =Yearly_Inputs!$B$9*Yearly_Inputs!$B$10*G11+Yearly_Inputs!$C$9*Yearly_Inputs!$C$10*F11+Yearly_Inputs!$D$9*Yearly_Inputs!$D$10*E11+Yearly_Inputs!$E$9*Yearly_Inputs!$E$10*D11+Yearly_Inputs!$F$9*Yearly_Inputs!$F$10*C11 -> 1081600
A23: Total benefits, all clients | C23: =C21+C22 -> 157144.65 | D23: =D21+D22 -> 554579.56 | E23: =E21+E22 -> 1095943.9 | F23: =F21+F22 -> 1754579.3 | G23: =G21+G22 -> 2506455.5
A24: Money raised from residents, all clients | C24: =Yearly_Inputs!$B$9*Yearly_Inputs!$B$10*Pools!C45 -> 3202500 | D24: =Yearly_Inputs!$B$9*Yearly_Inputs!$B$10*Pools!D45+Yearly_Inputs!$C$9*Yearly_Inputs!$C$10*Pools!C45 -> 7268000 | E24: =Yearly_Inputs!$B$9*Yearly_Inputs!$B$10*Pools!E45+Yearly_Inputs!$C$9*Yearly_Inputs!$C$10*Pools!D45+Yearly_Inputs!$D$9*Yearly_Inputs!$D$10*Pools!C45 -> 12038000 | F24: =Yearly_Inputs!$B$9*Yearly_Inputs!$B$10*Pools!F45+Yearly_Inputs!$C$9*Yearly_Inputs!$C$10*Pools!E45+Yearly_Inputs!$D$9*Yearly_Inputs!$D$10*Pools!D45+Yearly_Inputs!$E$9*Yearly_Inputs!$E$10*Pools!C45 -> 17900000 | G24: =Yearly_Inputs!$B$9*Yearly_Inputs!$B$10*Pools!G45+Yearly_Inputs!$C$9*Yearly_Inputs!$C$10*Pools!F45+Yearly_Inputs!$D$9*Yearly_Inputs!$D$10*Pools!E45+Yearly_Inputs!$E$9*Yearly_Inputs!$E$10*Pools!D45+Yearly_Inputs!$F$9*Yearly_Inputs!$F$10*Pools!C45 -> 23954000
A25: Resident investments made, all clients (count) | B25: count | C25: =Yearly_Inputs!$B$9*Yearly_Inputs!$B$10*Pools!C49 -> 6405 | D25: =Yearly_Inputs!$B$9*Yearly_Inputs!$B$10*Pools!D49+Yearly_Inputs!$C$9*Yearly_Inputs!$C$10*Pools!C49 -> 14536 | E25: =Yearly_Inputs!$B$9*Yearly_Inputs!$B$10*Pools!E49+Yearly_Inputs!$C$9*Yearly_Inputs!$C$10*Pools!D49+Yearly_Inputs!$D$9*Yearly_Inputs!$D$10*Pools!C49 -> 24076 | F25: =Yearly_Inputs!$B$9*Yearly_Inputs!$B$10*Pools!F49+Yearly_Inputs!$C$9*Yearly_Inputs!$C$10*Pools!E49+Yearly_Inputs!$D$9*Yearly_Inputs!$D$10*Pools!D49+Yearly_Inputs!$E$9*Yearly_Inputs!$E$10*Pools!C49 -> 35800 | G25: =Yearly_Inputs!$B$9*Yearly_Inputs!$B$10*Pools!G49+Yearly_Inputs!$C$9*Yearly_Inputs!$C$10*Pools!F49+Yearly_Inputs!$D$9*Yearly_Inputs!$D$10*Pools!E49+Yearly_Inputs!$E$9*Yearly_Inputs!$E$10*Pools!D49+Yearly_Inputs!$F$9*Yearly_Inputs!$F$10*Pools!C49 -> 47908
A26: Residents' profit, all clients | C26: =Yearly_Inputs!$B$9*Yearly_Inputs!$B$10*Pools!C50 -> 82163.299 | D26: =Yearly_Inputs!$B$9*Yearly_Inputs!$B$10*Pools!D50+Yearly_Inputs!$C$9*Yearly_Inputs!$C$10*Pools!C50 -> 335921.35 | E26: =Yearly_Inputs!$B$9*Yearly_Inputs!$B$10*Pools!E50+Yearly_Inputs!$C$9*Yearly_Inputs!$C$10*Pools!D50+Yearly_Inputs!$D$9*Yearly_Inputs!$D$10*Pools!C50 -> 762000.28 | F26: =Yearly_Inputs!$B$9*Yearly_Inputs!$B$10*Pools!F50+Yearly_Inputs!$C$9*Yearly_Inputs!$C$10*Pools!E50+Yearly_Inputs!$D$9*Yearly_Inputs!$D$10*Pools!D50+Yearly_Inputs!$E$9*Yearly_Inputs!$E$10*Pools!C50 -> 1355634.2 | G26: =Yearly_Inputs!$B$9*Yearly_Inputs!$B$10*Pools!G50+Yearly_Inputs!$C$9*Yearly_Inputs!$C$10*Pools!F50+Yearly_Inputs!$D$9*Yearly_Inputs!$D$10*Pools!E50+Yearly_Inputs!$E$9*Yearly_Inputs!$E$10*Pools!D50+Yearly_Inputs!$F$9*Yearly_Inputs!$F$10*Pools!C50 -> 2096095.9
