Workbook

Sheet Summary
A1: Township Green Loop – Executive Summary
A3: SDP University Hackathon 2026 · Theme: Planet · We run the platform; township developers pay to use it; residents invest in three green pools.
A5: Vendor (us, the platform)
A6: Vendor ROI (5-yr) | C6: Vendor net profit (5-yr) | E6: Vendor NPV
A7: =ROI!C16 -> 1.171918 | C7: =ROI!H10 -> 1434165.2 | E7: =ROI!E31 -> 778498.7
A9: Customer (township developers, all clients)
A10: Customer ROI (5-yr) | C10: Customer net profit (5-yr) | E10: Customer NPV
A11: =ROI!C17 -> 1.9631463 | C11: =ROI!H13 -> 3553672.7 | E11: =ROI!C39 -> 2080179.5
A13: ="Discount rate "&TEXT(Assumptions!$B$58,"0%")&" · ROI = (gain − cost) ÷ cost · Customer = benefit to developers minus what they pay us (Customer_ROI has SDP alone)." -> Discount rate 15% · ROI = (gain − cost) ÷ cost · Customer = benefit to developers minus what they pay us (Customer_ROI has SDP alone).
A15: Investor (resident) view: see the Investor_View sheet (minimum and maximum investment for each pool).
A17: Key takeaways
A18: • SDP gains from Year 1 even on cash alone: Year 1 costs only a RM20,000 set-up instalment, and the JV passes a 1% fee on residents' solar money to SDP. Half of the community saving is guaranteed in the contract.
A19: • Residents earn from Year 1 on solar and upgrades; EV is variable with a minimum-usage top-up.
A20: • We lose money in Year 1 (covered by a RM120,000 grant) and earn from Year 2, even if only one new developer signs that year. See Conservative_Test.
A22: Core prices
A23: ="Set-up fee RM"&TEXT(Assumptions!$B$38,"#,##0")&" (RM"&TEXT(Assumptions!$B$60,"#,##0")&" in Year 1, RM"&TEXT(Assumptions!$B$61,"#,##0")&" in Year 2) · Platform fee RM"&TEXT(Assumptions!$B$39,"#,##0")&" a year from Year 2 · Success fee "&TEXT(Assumptions!$B$40,"0.00%")&" (waived in Year 1) · "&TEXT(Assumptions!$B$41,"0.0%")&" a year on money invested · "&TEXT(Assumptions!$B$42,"0%")&" on mall redemptions · smaller developers pay pro rata" -> Set-up fee RM50,000 (RM20,000 in Year 1, RM30,000 in Year 2) · Platform fee RM72,000 a year from Year 2 · Success fee 0.75% (waived in Year 1) · 0.5% a year on money invested · 2% on mall redemptions · smaller developers pay pro rata
A25: Normal vs conservative (live, from Conservative_Test)
A26: Check | C26: Normal | E26: Conservative | G26: Normal | H26: Conservative
A27: 1. Customer (SDP) net gain, Year 1 | C27: =Conservative_Test!B28 -> 126768.55 | E27: =Conservative_Test!C28 -> 5808.8056 | G27: =Conservative_Test!E28 -> PASS | H27: =Conservative_Test!F28 -> PASS
A28: 2. Customer cash-only net gain, Year 1 (no community saving) | C28: =Conservative_Test!B29 -> 22768.55 | E28: =Conservative_Test!C29 -> 5808.8056 | G28: =Conservative_Test!E29 -> PASS | H28: =Conservative_Test!F29 -> PASS
A29: 2b. New developer net gain, its Year 1 | C29: =Conservative_Test!B30 -> 76061.13 | E29: =Conservative_Test!C30 -> 2323.5223 | G29: =Conservative_Test!E30 -> PASS | H29: =Conservative_Test!F30 -> PASS
A30: 3. Residents' profit, Year 1 (all pools, SDP) | C30: =Conservative_Test!B31 -> 82163.299 | E30: =Conservative_Test!C31 -> 50465.897 | G30: =Conservative_Test!E31 -> PASS | H30: =Conservative_Test!F31 -> PASS
A31: 4a. Solar investor return, Year 1 | C31: =Conservative_Test!B32 -> 0.04547563 | E31: =Conservative_Test!C32 -> 0.04547563 | G31: =Conservative_Test!E32 -> PASS | H31: =Conservative_Test!F32 -> PASS
A32: 4b. Upgrade investor return, Year 1 | C32: =Conservative_Test!B33 -> 0.05484129 | E32: =Conservative_Test!C33 -> 0.012947272 | G32: =Conservative_Test!E33 -> PASS | H32: =Conservative_Test!F33 -> PASS
A33: 4c. EV investor loss over the 7-year payback period | C33: =Conservative_Test!B34 -> 0 | E33: =Conservative_Test!C34 -> 0.4 | G33: =Conservative_Test!E34 -> PASS | H33: =Conservative_Test!F34 -> PASS
A34: 5. Vendor net profit, Year 2 | C34: =Conservative_Test!B35 -> 92228.355 | E34: =Conservative_Test!C35 -> 5033.9555 | G34: =Conservative_Test!E35 -> PASS | H34: =Conservative_Test!F35 -> PASS
A35: 6. Vendor net profit, 5 years | C35: =Conservative_Test!B36 -> 1434165.2 | E35: =Conservative_Test!C36 -> 131171.91 | G35: =Conservative_Test!E36 -> PASS | H35: =Conservative_Test!F36 -> PASS
A36: 7. NPV of vendor cash flows | C36: =Conservative_Test!B37 -> 778498.7 | E36: =Conservative_Test!C37 -> 22817.907 | G36: =Conservative_Test!E37 -> PASS | H36: =Conservative_Test!F37 -> PASS
A37: 8. Lowest cash balance in 5 years (with grant) | C37: =Conservative_Test!B38 -> 33918.505 | E37: =Conservative_Test!C38 -> 12403.716 | G37: =Conservative_Test!E38 -> PASS | H37: =Conservative_Test!F38 -> PASS
A38: 9. Vendor lowest yearly net profit, Years 2–5 | C38: =Conservative_Test!B39 -> 92228.355 | E38: =Conservative_Test!C39 -> 5033.9555 | G38: =Conservative_Test!E39 -> PASS | H38: =Conservative_Test!F39 -> PASS
A39: All checks | G39: =Conservative_Test!E40 -> ALL PASS | H39: =Conservative_Test!F40 -> ALL PASS

Sheet Investor_View
A1: Investor_View – what a resident gets from each pool, at the minimum and maximum investment
A2: All numbers link to Investor_ROI and Assumptions. Change the limits in Assumptions rows 96–101.
A4: Per resident | B4: Solar pool (low risk) | D4: Upgrade pool (medium risk) | F4: EV pool (high risk)
B5: Minimum | C5: Maximum | D5: Minimum | E5: Maximum | F5: Minimum | G5: Maximum
A6: Invest | B6: =Assumptions!$B$96 -> 100 | C6: =Assumptions!$B$97 -> 2000 | D6: =Assumptions!$B$98 -> 100 | E6: =Assumptions!$B$99 -> 1000 | F6: =Assumptions!$B$100 -> 100 | G6: =Assumptions!$B$101 -> 500
A7: Investment rate (per year) | B7: =Investor_ROI!B6 -> 0.05 | C7: =Investor_ROI!B6 -> 0.05 | D7: =Investor_ROI!B15 -> 0.065 | E7: =Investor_ROI!B15 -> 0.065 | F7: =Investor_ROI!B57 -> 0.066187268 | G7: =Investor_ROI!B57 -> 0.066187268
A8: Rate type | B8: Fixed payout backed by tenant power payments (not roof leasing); minimum 4.5% | C8: Fixed payout backed by tenant power payments (not roof leasing); minimum 4.5% | D8: Fixed; installer guarantees shop savings | E8: Fixed; installer guarantees shop savings | F8: Variable, not guaranteed; partners top up to 60 kWh/day (capped) | G8: Variable, not guaranteed; partners top up to 60 kWh/day (capped)
A9: Money paid back over | B9: =Assumptions!$B$20&" years, monthly" -> 5 years, monthly | C9: =Assumptions!$B$20&" years, monthly" -> 5 years, monthly | D9: =Assumptions!$B$27&" years, monthly" -> 3 years, monthly | E9: =Assumptions!$B$27&" years, monthly" -> 3 years, monthly | F9: =Investor_ROI!B30&" years, from charging income" -> 7 years, from charging income | G9: =Investor_ROI!B30&" years, from charging income" -> 7 years, from charging income
A10: Normal case
A11: Total received | B11: =B6*(Investor_ROI!B46)/Investor_ROI!B45 -> 113.2274 | C11: =C6*(Investor_ROI!B46)/Investor_ROI!B45 -> 2264.548 | D11: =D6*((Investor_ROI!B50-Investor_ROI!B51))/Investor_ROI!B45 -> 110.33641 | E11: =E6*((Investor_ROI!B50-Investor_ROI!B51))/Investor_ROI!B45 -> 1103.3641 | F11: =F6*(Investor_ROI!B55)/Investor_ROI!B45 -> 128.70961 | G11: =G6*(Investor_ROI!B55)/Investor_ROI!B45 -> 643.54803
A12: Return over the payback period (RM) | B12: =B6*(Investor_ROI!B46)/Investor_ROI!B45-B6 -> 13.227402 | C12: =C6*(Investor_ROI!B46)/Investor_ROI!B45-C6 -> 264.54804 | D12: =D6*((Investor_ROI!B50-Investor_ROI!B51))/Investor_ROI!B45-D6 -> 10.33641 | E12: =E6*((Investor_ROI!B50-Investor_ROI!B51))/Investor_ROI!B45-E6 -> 103.3641 | F12: =F6*(Investor_ROI!B55)/Investor_ROI!B45-F6 -> 28.709607 | G12: =G6*(Investor_ROI!B55)/Investor_ROI!B45-G6 -> 143.54803
A13: Return over the payback period (%) | B13: =(Investor_ROI!B46)/Investor_ROI!B45-1 -> 0.13227402 | C13: =(Investor_ROI!B46)/Investor_ROI!B45-1 -> 0.13227402 | D13: =((Investor_ROI!B50-Investor_ROI!B51))/Investor_ROI!B45-1 -> 0.1033641 | E13: =((Investor_ROI!B50-Investor_ROI!B51))/Investor_ROI!B45-1 -> 0.1033641 | F13: =(Investor_ROI!B55)/Investor_ROI!B45-1 -> 0.28709607 | G13: =(Investor_ROI!B55)/Investor_ROI!B45-1 -> 0.28709607
A14: Conservative case (Pools_Scenarios sheet)
A15: Effective rate (per year) | B15: =Investor_ROI!C8 -> 0.05 | C15: =Investor_ROI!C8 -> 0.05 | D15: =Investor_ROI!C53 -> 0.032304876 | E15: =Investor_ROI!C53 -> 0.032304876 | F15: =Investor_ROI!C57 -> -0.11351477 | G15: =Investor_ROI!C57 -> -0.11351477
A16: Total received | B16: =B6*(Investor_ROI!C46)/Investor_ROI!C45 -> 113.2274 | C16: =C6*(Investor_ROI!C46)/Investor_ROI!C45 -> 2264.548 | D16: =D6*((Investor_ROI!C50-Investor_ROI!C51))/Investor_ROI!C45 -> 105.05843 | E16: =E6*((Investor_ROI!C50-Investor_ROI!C51))/Investor_ROI!C45 -> 1050.5843 | F16: =F6*(Investor_ROI!C55)/Investor_ROI!C45 -> 60 | G16: =G6*(Investor_ROI!C55)/Investor_ROI!C45 -> 300
A17: Return over the payback period (RM) | B17: =B6*(Investor_ROI!C46)/Investor_ROI!C45-B6 -> 13.227402 | C17: =C6*(Investor_ROI!C46)/Investor_ROI!C45-C6 -> 264.54804 | D17: =D6*((Investor_ROI!C50-Investor_ROI!C51))/Investor_ROI!C45-D6 -> 5.0584278 | E17: =E6*((Investor_ROI!C50-Investor_ROI!C51))/Investor_ROI!C45-E6 -> 50.584278 | F17: =F6*(Investor_ROI!C55)/Investor_ROI!C45-F6 -> -40 | G17: =G6*(Investor_ROI!C55)/Investor_ROI!C45-G6 -> -200
A18: Return over the payback period (%) | B18: =(Investor_ROI!C46)/Investor_ROI!C45-1 -> 0.13227402 | C18: =(Investor_ROI!C46)/Investor_ROI!C45-1 -> 0.13227402 | D18: =((Investor_ROI!C50-Investor_ROI!C51))/Investor_ROI!C45-1 -> 0.050584278 | E18: =((Investor_ROI!C50-Investor_ROI!C51))/Investor_ROI!C45-1 -> 0.050584278 | F18: =(Investor_ROI!C55)/Investor_ROI!C45-1 -> -0.4 | G18: =(Investor_ROI!C55)/Investor_ROI!C45-1 -> -0.4
A20: ="Most one resident can put in across all three pools: RM"&TEXT(Assumptions!$B$97+Assumptions!$B$99+Assumptions!$B$101,"#,##0")&". Smallest start: RM"&TEXT(MIN(Assumptions!$B$96,Assumptions!$B$98,Assumptions!$B$100),"#,##0")&" in any one pool." -> Most one resident can put in across all three pools: RM3,500. Smallest start: RM100 in any one pool.
A21: • Payback period: solar 5 years, upgrades 3 years, EV 7 years. Returns are over each pool's own payback period. The return % is the same at the minimum and the maximum; only the RM amount changes.
A22: • Solar: residents are funders, not roof landlords. The developer/JV owns and runs the panels; tenants, malls and factories pay for the power, and residents' payouts are paid first. Different from SDP's CREAM roof-leasing project in Elmina.
A23: • Upgrades: paid back monthly over 3 years. Totals are after expected shop defaults and the bad-debt reserve.
A24: • EV: the thinnest pool. A licensed charge point operator (CPO) co-invests half and runs the chargers. Payouts come only from charging profit; the developer and platform take their 10% shares only after residents get their money back. If usage falls below 60 kWh/day, partners top up (capped at RM3,000 per charger a year). Price wars, cost rises and a refused government grant are NOT covered: in the conservative case residents get back only about 60% of their money.
A25: • Risk disclosure: none of the pools is a deposit and none is covered by PIDM. Money is held by a licensed platform, never by us. Caps (RM2,000 / 1,000 / 500) sit well inside the retail limit of RM10,000 per issuer and RM50,000 a year [R17].

Sheet Business_Case
A1: Business_Case – who pays whom, investment rules, customers, stakeholders and competition
A2: Vendor = us (the platform company); SDP and other township developers are our customers. Green cells are live links to the model.
A4: 1. Business model – who pays whom
A5: Party | B5: Puts in | C5: Gets out | D5: Live number
A6: Residents (investors) | B6: From RM100 per pool through a licensed market operator (RMO). Caps: Solar RM2,000, Upgrades RM1,000, EV RM500. | C6: Monthly payouts to the app wallet; +10% when spent at SDP malls (shop-funded); green points and badges. Solar 5% fixed (minimum 4.5%), Upgrades 6.5% fixed, EV variable (~6.6% expected, not guaranteed). | D6: ="RM"&TEXT(Pools_Scenarios!C50,"#,##0;(#,##0)") -> RM82,163
A7: Shop tenants | B7: Nothing upfront. Pay for solar power about 15% below grid; repay upgrades from 80% of bill savings; installer guarantees at least RM800 a month saving. | C7: Lower bills now; keep 100% of the savings after 3 years; energy dashboard.
A8: EV drivers | B8: Pay RM1.40/kWh (DC 60 kW) or RM1.00/kWh (AC 22 kW); peak and off-peak prices; idle fee after 15 minutes. | C8: Charging at the mall while they shop.
A9: SDP and other developers (OUR CUSTOMERS) | B9: Roofs, malls, tenant relationships, community programme team. Pay us: set-up RM50,000 (RM20,000 in Year 1), platform fee RM72,000 a year from Year 2, usage fees. Bear 50% of the RMO fee. | C9: Cheaper money for solar, JV fee, upgrade fees, extra mall rent, REC sales, community-programme saving, ESG/carbon data for the sustainability report. | D9: ="RM"&TEXT(Customer_ROI!C8,"#,##0;(#,##0)") -> RM126,769
A10: Us – Township Green Loop (VENDOR) | B10: Build and run the app: wallet, points, bills, rewards, impact data, AI advisor. Lean team of 2 founders. | C10: Set-up and platform fees, 0.75% success fee (waived in Year 1), 0.5% a year on money invested, 2% on mall redemptions, shop featured offers and dashboards, REC service fee, 10% of residents' EV profit after they recover their money. | D10: ="Y1 "&TEXT(ROI!C10,"#,##0;(#,##0)")&" · Y2 "&TEXT(ROI!D10,"#,##0;(#,##0)") -> Y1 (86,081) · Y2 92,228
A11: Licensed platform (RMO), e.g. pitchIN or Ethis | B11: Holds residents' money in trust, KYC, regulatory compliance. We are the front end only. | C11: Success fee about 6% + SST of money raised, paid by the issuer (developer 50%, JV/SPV 50%) [R19].
A12: Charge point operator (ChargEV, Gentari, DC Handal, TNB Electron…) | B12: Co-funds 50% of each charger, applies for the MARii grant, runs operations, maintenance, SLA and customer service. | C12: 50% of charging profit plus the service fee; pays 34% of any usage top-up.
A13: SDP × GSPARX JV | B13: Owns and runs the solar assets; funds the 70% residents do not. | C13: Power sales to tenants; lower cost of capital (5% to residents vs 8.5% own money).
A15: 2. Investment rules
A16: Rule | B16: What | C16: Why / source | D16: Where enforced
A17: Who can invest | B17: Verified township residents, plus supporters: family of residents, people who work in the township, former residents. KYC through the RMO for both. | C17: Residents first, supporters welcome: keeps the township at the centre while widening the investor base to fill each raise | D17: RMO onboarding; profile role (resident / supporter)
A18: Resident priority | B18: Residents get the first 14 days of every raise and at least 70% of each pool | C18: Benefits stay local | D18: Raise schedule on each pool
A19: Minimum / caps | B19: From RM100. Per resident: Solar RM2,000, Upgrades RM1,000, EV RM500 | C19: Retail limit RM10,000 per issuer and RM50,000 per 12 months [R17] | D19: Database trigger (pools.min_invest / max_invest)
A20: 12-month limit | B20: RM50,000 in total across all pools in any 12 months | C20: SC retail limit [R17] | D20: Database trigger
A21: Risk statement | B21: Must read and accept each pool's risk statement before the first investment | C21: Investor education duty of the operator | D21: risk_acknowledgements table
A22: Who holds money | B22: SC-recognised market operator holds funds in trust; the app is the front end only | C22: We never touch investor money | D22: Contract with RMO
A23: Solar share | B23: Residents fund at most 30% of each solar asset (20% in the conservative test) | C23: Tenant power payments cover payouts about 1.6x at 30% | D23: Assumptions row 111
A24: Upgrade shops | B24: Only high-energy shops with 3+ years left on lease and a deposit SDP holds; installer guarantees a minimum saving | C24: Tenant credit risk | D24: Shop selection + installer contract
A25: EV exposure | B25: EV under ~10% of each raise; RM500 cap; 'capital can fall' warning; developer and platform shares wait until residents recover their money | C25: Highest-risk pool (EV_Pilot) | D25: Pool cap + app warning
A26: Release of funds | B26: Each asset's money is released only when that asset is ready | C26: No idle money; explains partial Year-1 payouts | D26: RMO escrow
A27: Payouts | B27: Monthly to the app wallet; withdraw, reinvest or spend at SDP malls with +10% | C27: Proposal | D27: wallet_transactions, spend_at_mall()
... A30: Disclosure | B30: Show risk rating, expected payout, total payback and carbon saved before every investment | C30: Investor education | D30: Invest page
A32: 3. Target customers
A33: Segment | B33: Who | C33: Hook | D33: Evidence
A34: Our customer – township developers | B34: SDP first (28 townships and developments [R5]); then other township developers at about 60% of SDP's size | C34: Gain from Year 1; ESG data; tenant retention; mall footfall | D34: ="RM"&TEXT(Customer_ROI!C8,"#,##0;(#,##0)") -> RM126,769
A35: End users – residents with savings | B35: Residents of SDP townships with savings to put to work | C35: 5–6.5% on low-risk pools vs a 12-month FD board rate of about 1.9% [R10]. EPF paid 6.15% for 2025 [R11], so we are a complement, not a replacement.
A36: Active mall shoppers | B36: Residents already using SDP malls | C36: +10% wallet bonus and points make the wallet worth keeping
A37: Supporters | B37: Family of residents (e.g. children working in other states), township workers, former residents | C37: Back the township they care about; same pools, rates and caps; spend points and mall credits when they visit
A38: Shop tenants (B2B) | B38: High-energy shops in KL East Mall, Elmina Lakeside Mall, KLGCC Mall | C38: Lower bills with no upfront cost
A39: Partners | B39: GSPARX/TNB (solar), charge point operator, licensed RMO | C39: Volume, co-branding, ESG story
A41: 4. Stakeholders – what we show each one
A42: Stakeholder | B42: What they care about | C42: What we show / ask | D42: Live number
A43: SDP leadership (our buyer) | B43: Cost, fees, footfall, ESG reporting | C43: Customer_ROI: SDP gains from Year 1; 5-year developer ROI; carbon data. Ask: Year-1 pilot at one township. | D43: ="RM"&TEXT(ROI!H13,"#,##0;(#,##0)") -> RM3,553,673
A44: Mall managers / leasing | B44: Tenant retention, rent | C44: Energy-upgrade pilot with 5–10 shops; extra sales earn only the turnover rent (about 1%), not average rent
A45: Shop tenants | B45: Lower bills, no capex | C45: Solar 15% below grid; 80:20 savings split, then 100% to the shop
A46: Residents | B46: Safe-ish return, local impact | C46: Investor_View: return over each pool's payback period at min and max, risk labels
...

Sheet Assumptions
A1: Township Green Loop – Business Plan Assumptions
A2: Blue = input you can change · Yellow = key assumption to check · Black = formula. All money in RM. Yearly inputs (by client year) are in the table at the bottom.
A4: Input | B4: Value | C4: Unit | D4: Source / note
A5: General
A6: Model Year 1 (calendar year) | B6: 2028 | C6: year | D6: Platform goes live after the hackathon pilot.
A7: Average investment per resident | B7: 500 | C7: RM | D7: Assumption. Each pool has its own minimum and maximum (Assumptions rows 96–101).
A8: Share of resident payouts spent at the developer's malls | B8: 0.3 | C8: % | D8: Assumption. Not survey-validated.
A9: Mall redemption bonus (paid by participating shops as a promotion) | B9: 0.1 | C9: % | D9: Design choice. Shops fund it, so it costs the developer nothing.
A10: Turnover rent the mall earns on extra shop sales | B10: 0.01 | C10: % of sales | D10: Assumption: turnover rent of about 1% of gross sales on top of base rent; confirm with SDP leasing.
A11: Average electricity cost for shops (low-voltage commercial) | B11: =Assumptions!$B$102 -> 0.5068 | C11: RM/kWh | D11: Links to row 102: 50.7 sen/kWh low-voltage non-domestic tariff, 1 Jul 2025 – 31 Dec 2027 [R6].
A12: Grid emission factor, Peninsular Malaysia 2024 | B12: 0.74 | C12: tCO2e/MWh | D12: Energy Commission, Grid Emission Factor 2022–2024 (provisional) [R7].
A13: SDP yearly spend on community programmes and spaces | B13: 20800000 | C13: RM/yr | D13: SDP Integrated Report 2024 key highlights: 70,000+ beneficiaries of community programmes and spaces, RM20.8 million total economic spend [R3].
A14: Share of solar funding saving kept by the developer | B14: 0.5 | C14: % | D14: Assumption. Solar assets sit in the SDP × GSPARX joint venture [R1]; the split is not public, so 50% is used.
A15: Pool 1 – Rooftop solar (residents fund it; the developer/JV owns and runs it – not roof leasing)
A16: Installed solar cost | B16: 3200 | C16: RM/kWp | D16: Assumption: commercial rooftop system including SST, mounting and grid works. Confirm with installer quotes.
A17: Solar output per kWp | B17: 1250 | C17: kWh/kWp/yr | D17: Conservative assumption. An academic study of a 216 kWp grid-connected system in Malaysia implies about 1,450 kWh/kWp a year [R25].
A18: Share of each solar asset funded by residents | B18: =Assumptions!$B$111 -> 0.3 | C18: % | D18: Links to row 111 (30%); the conservative case uses row 112 (20%). At 30%, tenant power payments cover payouts about 1.6 times (Investor_ROI).
A19: Payout rate to residents (solar) | B19: 0.05 | C19: % a year | D19: Design choice. Above the 12-month FD board rate of about 1.9% [R10] and below EPF's 6.15% for 2025 [R11].
A20: Solar payout tenure | B20: 5 | C20: years | D20: Design choice.
A21: Return the JV would otherwise need on its own money | B21: 0.085 | C21: % a year | D21: Assumption: return the JV would need on its own money for a solar project.
A22: Pool 2 – Shop energy upgrades
A23: Upgrade cost per shop | B23: 20000 | C23: RM | D23: Assumption (efficient air-con, fridges, LED). Get supplier quotes.
A24: Bill saving per shop | B24: 1000 | C24: RM/month | D24: Assumption: about 25% of a RM4,000 monthly bill. Confirm with energy audits.
A25: Share of savings used to repay residents | B25: 0.8 | C25: % | D25: Malaysian ESCO shared-savings contracts use 80:20 and 75:25 splits (MAESCO) [R20].
A26: Payout rate to residents (upgrades) | B26: 0.065 | C26: % a year | D26: Design choice: higher than solar to reflect shop default risk.
A27: Upgrade payout tenure | B27: 3 | C27: years | D27: Design choice.
A28: Developer's share of the monthly safety margin | B28: 0.5 | C28: % | D28: Design choice. Other half kept as a bad-debt reserve.
A29: Pool 3 – EV charging (DC 60 kW + AC 22 kW, run by a licensed charge point operator)
A30: Installed cost per charger, blended DC/AC mix (before grant) | B30: =Assumptions!$B$115*Assumptions!$B$116+(1-Assumptions!$B$115)*Assumptions!$B$117 -> 62500 | C30: RM | D30: Formula = DC share × DC cost + AC share × AC cost (rows 115–117).
A31: Share of each charger's net cost funded by residents | B31: 0.5 | C31: % | D31: Design choice. The charge point operator (CPO) co-invests the other 50% and runs the chargers (operations, maintenance, SLA, customer service).
A32: DC 60 kW standard charging price | B32: 1.4 | C32: RM/kWh | D32: ChargEV at AEON Mall Cheras Selatan, Jul 2026: 60 kW DC RM1.40, 22 kW AC RM1.00, 180 kW DC RM1.60 per kWh [R24].
A33: Payment and app costs | B33: 0.03 | C33: % of charging revenue | D33: Assumption: payment gateway about 1.5–3% plus app costs.
A34: DC 60 kW maintenance and CPO service fee | B34: 10000 | C34: RM/yr | D34: Assumption: maintenance, warranty and the CPO's service (SLA, customer service), about 10% of installed cost a year.
A35: Energy sold per charger per day | B35: =Assumptions!$B$105*Assumptions!$B$106 -> 60 | C35: kWh/day | D35: Formula = sessions × kWh per session (rows 105–106). Usage is the biggest EV risk.
A36: Developer's share of residents' charging profit (site host) | B36: 0.1 | C36: % | D36: Split of residents' charging profit: residents 70% (row 132), developer 10%, platform 10% (row 133), O&M reserve 10% (row 134). Developer and platform shares wait until residents recover their money (row 135).
A37: Vendor pricing (what we charge each developer)
A38: Set-up fee (total, billed over client Years 1 and 2) | B38: =Assumptions!$B$60+Assumptions!$B$61 -> 50000 | C38: RM | D38: Formula = Year 1 instalment + Year 2 instalment (rows 60–61).
A39: Annual platform fee (from client's second year) | B39: 72000 | C39: RM/yr | D39: Our price for an SDP-size client (RM6,000 a month). Waived in the first year as a pilot. Smaller clients pay pro rata to size.
A40: Success fee on money raised through the platform | B40: 0.0075 | C40: % of raised | D40: Our price, separate from the licensed platform's fee (row 148). Waived in client Year 1 (row 62).
A41: Yearly fee on residents' money still invested | B41: 0.005 | C41: % a year | D41: Our price, from client's second year.
...

Sheet Pools_Scenarios
A1: Pools – what happens inside one client (SDP size), by the client's year on the platform
A2: Money raised, money still invested, payouts and impact for the three pools (other clients are scaled from this). Conservative stress inputs are in the table from row 81.
A4: Item | B4: Unit | C4: Year 1 | D4: Year 2 | E4: Year 3 | F4: Year 4 | G4: Year 5
A5: Timing factors (money is raised mid-year on average)
A6: Year since money was raised | C6: 1 | D6: 2 | E6: 3 | F6: 4 | G6: 5
A7: Solar: share of money still owed at year end | C7: =((1+Assumptions!$B$19)^Assumptions!$B$20-(1+Assumptions!$B$19)^C6)/((1+Assumptions!$B$19)^Assumptions!$B$20-1) -> 0.8190252 | D7: =((1+Assumptions!$B$19)^Assumptions!$B$20-(1+Assumptions!$B$19)^D6)/((1+Assumptions!$B$19)^Assumptions!$B$20-1) -> 0.62900166 | E7: =((1+Assumptions!$B$19)^Assumptions!$B$20-(1+Assumptions!$B$19)^E6)/((1+Assumptions!$B$19)^Assumptions!$B$20-1) -> 0.42947695 | F7: =((1+Assumptions!$B$19)^Assumptions!$B$20-(1+Assumptions!$B$19)^F6)/((1+Assumptions!$B$19)^Assumptions!$B$20-1) -> 0.219976 | G7: =((1+Assumptions!$B$19)^Assumptions!$B$20-(1+Assumptions!$B$19)^G6)/((1+Assumptions!$B$19)^Assumptions!$B$20-1) -> 0
A8: Solar: average share still invested | C8: =0.5 -> 0.5 | D8: =(1+C7)/2 -> 0.9095126 | E8: =(C7+D7)/2 -> 0.72401343 | F8: =(D7+E7)/2 -> 0.52923931 | G8: =(E7+F7)/2 -> 0.32472647
A9: Payout timing (half year in first year) | C9: =0.5 -> 0.5 | D9: =1 -> 1 | E9: =1 -> 1 | F9: =1 -> 1 | G9: =1 -> 1
A10: Upgrades: share still owed at year end | C10: =MAX(0,((1+Assumptions!$B$26)^Assumptions!$B$27-(1+Assumptions!$B$26)^C6)/((1+Assumptions!$B$26)^Assumptions!$B$27-1)) -> 0.6874243 | D10: =MAX(0,((1+Assumptions!$B$26)^Assumptions!$B$27-(1+Assumptions!$B$26)^D6)/((1+Assumptions!$B$26)^Assumptions!$B$27-1)) -> 0.35453118 | E10: =MAX(0,((1+Assumptions!$B$26)^Assumptions!$B$27-(1+Assumptions!$B$26)^E6)/((1+Assumptions!$B$26)^Assumptions!$B$27-1)) -> 0 | F10: =MAX(0,((1+Assumptions!$B$26)^Assumptions!$B$27-(1+Assumptions!$B$26)^F6)/((1+Assumptions!$B$26)^Assumptions!$B$27-1)) -> 0 | G10: =MAX(0,((1+Assumptions!$B$26)^Assumptions!$B$27-(1+Assumptions!$B$26)^G6)/((1+Assumptions!$B$26)^Assumptions!$B$27-1)) -> 0
A11: Upgrades: average share still invested | C11: =0.5 -> 0.5 | D11: =(1+C10)/2 -> 0.84371215 | E11: =(C10+D10)/2 -> 0.52097774 | F11: =(D10+E10)/2 -> 0.17726559 | G11: =(E10+F10)/2 -> 0
A12: Upgrades: share of year a shop is repaying | C12: =0.5 -> 0.5 | D12: =1 -> 1 | E12: =1 -> 1 | F12: =0.5 -> 0.5 | G12: =0 -> 0
A13: EV: average share still invested (paid back evenly over the EV payback period) | C13: =0.5*(1+(1-0.5/Assumptions!$B$137))/2 -> 0.48214286 | D13: =MAX(0,1-1/Assumptions!$B$137) -> 0.85714286 | E13: =MAX(0,1-2/Assumptions!$B$137) -> 0.71428571 | F13: =MAX(0,1-3/Assumptions!$B$137) -> 0.57142857 | G13: =MAX(0,1-4/Assumptions!$B$137) -> 0.42857143
A14: EV: share of money paid back in the year | C14: =0.5/Assumptions!$B$137 -> 0.071428571 | D14: =IF(2-0.5<=Assumptions!$B$137,1/Assumptions!$B$137,0) -> 0.14285714 | E14: =IF(3-0.5<=Assumptions!$B$137,1/Assumptions!$B$137,0) -> 0.14285714 | F14: =IF(4-0.5<=Assumptions!$B$137,1/Assumptions!$B$137,0) -> 0.14285714 | G14: =IF(5-0.5<=Assumptions!$B$137,1/Assumptions!$B$137,0) -> 0.14285714
A15: Pool 1 – Rooftop solar
A16: New solar capacity with resident share | B16: MW | C16: =Assumptions!$B$155 -> 3 | D16: =Assumptions!$C$155 -> 3 | E16: =Assumptions!$D$155 -> 4 | F16: =Assumptions!$E$155 -> 5 | G16: =Assumptions!$F$155 -> 5
A17: Money raised from residents | B17: RM | C17: =C16*1000*Assumptions!$B$16*Assumptions!$B$18 -> 2880000 | D17: =D16*1000*Assumptions!$B$16*Assumptions!$B$18 -> 2880000 | E17: =E16*1000*Assumptions!$B$16*Assumptions!$B$18 -> 3840000 | F17: =F16*1000*Assumptions!$B$16*Assumptions!$B$18 -> 4800000 | G17: =G16*1000*Assumptions!$B$16*Assumptions!$B$18 -> 4800000
A18: Residents' money still invested (average) | B18: RM | C18: =C17*C8 -> 1440000 | D18: =C17*D8+D17*C8 -> 4059396.3 | E18: =C17*E8+D17*D8+E17*C8 -> 6624555 | F18: =C17*F8+D17*E8+E17*D8+F17*C8 -> 9501896.3 | G18: =C17*G8+D17*F8+E17*E8+F17*D8+G17*C8 -> 12005294
A19: Yearly payment per RM1 raised | B19: factor | C19: =PMT(Assumptions!$B$19,Assumptions!$B$20,-1) -> 0.2309748 | D19: =PMT(Assumptions!$B$19,Assumptions!$B$20,-1) -> 0.2309748 | E19: =PMT(Assumptions!$B$19,Assumptions!$B$20,-1) -> 0.2309748 | F19: =PMT(Assumptions!$B$19,Assumptions!$B$20,-1) -> 0.2309748 | G19: =PMT(Assumptions!$B$19,Assumptions!$B$20,-1) -> 0.2309748
A20: Payouts to residents | B20: RM | C20: =(C17*C9)*C19 -> 332603.71 | D20: =(C17*D9+D17*C9)*D19 -> 997811.13 | E20: =(C17*E9+D17*D9+E17*C9)*E19 -> 1773886.4 | F20: =(C17*F9+D17*E9+E17*D9+F17*C9)*F19 -> 2771697.6 | G20: =(C17*G9+D17*F9+E17*E9+F17*D9+G17*C9)*G19 -> 3880376.6
A21: Solar capacity running (average) | B21: MW | C21: =C16*C9 -> 1.5 | D21: =C16*D9+D16*C9 -> 4.5 | E21: =C16*E9+D16*D9+E16*C9 -> 8 | F21: =C16*F9+D16*E9+E16*D9+F16*C9 -> 12.5 | G21: =C16*G9+D16*F9+E16*E9+F16*D9+G16*C9 -> 17.5
A22: Solar power produced | B22: MWh | C22: =C21*Assumptions!$B$17 -> 1875 | D22: =D21*Assumptions!$B$17 -> 5625 | E22: =E21*Assumptions!$B$17 -> 10000 | F22: =F21*Assumptions!$B$17 -> 15625 | G22: =G21*Assumptions!$B$17 -> 21875
A23: CO2 avoided by solar | B23: tCO2e | C23: =C22*Assumptions!$B$12 -> 1387.5 | D23: =D22*Assumptions!$B$12 -> 4162.5 | E23: =E22*Assumptions!$B$12 -> 7400 | F23: =F22*Assumptions!$B$12 -> 11562.5 | G23: =G22*Assumptions!$B$12 -> 16187.5
A24: Pool 2 – Shop energy upgrades
A25: New shops upgraded | B25: shops | C25: =Assumptions!$B$156 -> 15 | D25: =Assumptions!$C$156 -> 25 | E25: =Assumptions!$D$156 -> 10 | F25: =Assumptions!$E$156 -> 10 | G25: =Assumptions!$F$156 -> 10
A26: Money raised from residents | B26: RM | C26: =C25*Assumptions!$B$23 -> 300000 | D26: =D25*Assumptions!$B$23 -> 500000 | E26: =E25*Assumptions!$B$23 -> 200000 | F26: =F25*Assumptions!$B$23 -> 200000 | G26: =G25*Assumptions!$B$23 -> 200000
A27: Residents' money still invested (average) | B27: RM | C27: =C26*C11 -> 150000 | D27: =C26*D11+D26*C11 -> 503113.64 | E27: =C26*E11+D26*D11+E26*C11 -> 678149.4 | F27: =C26*F11+D26*E11+E26*D11+F26*C11 -> 582410.97 | G27: =C26*G11+D26*F11+E26*E11+F26*D11+G26*C11 -> 461570.77
A28: Shops repaying (shop-years) | B28: shop-yrs | C28: =C25*C12 -> 7.5 | D28: =C25*D12+D25*C12 -> 27.5 | E28: =C25*E12+D25*D12+E25*C12 -> 45 | F28: =C25*F12+D25*E12+E25*D12+F25*C12 -> 47.5 | G28: =C25*G12+D25*F12+E25*E12+F25*D12+G25*C12 -> 37.5
A29: Yearly payout per shop to residents | B29: RM | C29: =PMT(Assumptions!$B$26/12,Assumptions!$B$27*12,-Assumptions!$B$23)*12 -> 7355.7607 | D29: =PMT(Assumptions!$B$26/12,Assumptions!$B$27*12,-Assumptions!$B$23)*12 -> 7355.7607 | E29: =PMT(Assumptions!$B$26/12,Assumptions!$B$27*12,-Assumptions!$B$23)*12 -> 7355.7607 | F29: =PMT(Assumptions!$B$26/12,Assumptions!$B$27*12,-Assumptions!$B$23)*12 -> 7355.7607 | G29: =PMT(Assumptions!$B$26/12,Assumptions!$B$27*12,-Assumptions!$B$23)*12 -> 7355.7607
A30: Payouts to residents | B30: RM | C30: =C28*C29 -> 55168.205 | D30: =D28*D29 -> 202283.42 | E30: =E28*E29 -> 331009.23 | F30: =F28*F29 -> 349398.63 | G30: =G28*G29 -> 275841.03
A31: Safety margin per shop-year (repayment counted − payout) | B31: RM | C31: =C56*12-C29 -> 2244.2393 | D31: =D56*12-D29 -> 2244.2393 | E31: =E56*12-E29 -> 2244.2393 | F31: =F56*12-F29 -> 2244.2393 | G31: =G56*12-G29 -> 2244.2393
A32: Savings shops keep | B32: RM | C32: =C28*Assumptions!$B$24*12*(1-Assumptions!$B$25) -> 18000 | D32: =D28*Assumptions!$B$24*12*(1-Assumptions!$B$25) -> 66000 | E32: =E28*Assumptions!$B$24*12*(1-Assumptions!$B$25) -> 108000 | F32: =F28*Assumptions!$B$24*12*(1-Assumptions!$B$25) -> 114000 | G32: =G28*Assumptions!$B$24*12*(1-Assumptions!$B$25) -> 90000
A33: Electricity saved | B33: MWh | C33: =C28*Assumptions!$B$24*12/Assumptions!$B$11/1000 -> 177.58485 | D33: =D28*Assumptions!$B$24*12/Assumptions!$B$11/1000 -> 651.14444 | E33: =E28*Assumptions!$B$24*12/Assumptions!$B$11/1000 -> 1065.5091 | F33: =F28*Assumptions!$B$24*12/Assumptions!$B$11/1000 -> 1124.704 | G33: =G28*Assumptions!$B$24*12/Assumptions!$B$11/1000 -> 887.92423
A34: CO2 avoided by upgrades | B34: tCO2e | C34: =C33*Assumptions!$B$12 -> 131.41279 | D34: =D33*Assumptions!$B$12 -> 481.84688 | E34: =E33*Assumptions!$B$12 -> 788.47672 | F34: =F33*Assumptions!$B$12 -> 832.28098 | G34: =G33*Assumptions!$B$12 -> 657.06393
A35: Pool 3 – EV charging
A36: New EV chargers | B36: chargers | C36: =Assumptions!$B$157 -> 1 | D36: =Assumptions!$C$157 -> 2 | E36: =Assumptions!$D$157 -> 2 | F36: =Assumptions!$E$157 -> 2 | G36: =Assumptions!$F$157 -> 2
A37: Money raised from residents (net cost after grant × residents' share) | B37: RM | C37: =C36*EV_Pilot!$B$46*Assumptions!$B$31 -> 22500 | D37: =D36*EV_Pilot!$B$46*Assumptions!$B$31 -> 45000 | E37: =E36*EV_Pilot!$B$46*Assumptions!$B$31 -> 45000 | F37: =F36*EV_Pilot!$B$46*Assumptions!$B$31 -> 45000 | G37: =G36*EV_Pilot!$B$46*Assumptions!$B$31 -> 45000
A38: Residents' money still invested (average) | B38: RM | C38: =C37*C13 -> 10848.214 | D38: =C37*D13+D37*C13 -> 40982.143 | E38: =C37*E13+D37*D13+E37*C13 -> 76339.286 | F38: =C37*F13+D37*E13+E37*D13+F37*C13 -> 105267.86 | G38: =C37*G13+D37*F13+E37*E13+F37*D13+G37*C13 -> 127767.86
A39: Chargers running (charger-years) | B39: chg-yrs | C39: =C36*C9 -> 0.5 | D39: =C36*D9+D36*C9 -> 2 | E39: =C36*E9+D36*D9+E36*C9 -> 4 | F39: =C36*F9+D36*E9+E36*D9+F36*C9 -> 6 | G39: =C36*G9+D36*F9+E36*E9+F36*D9+G36*C9 -> 8
A40: Net charging profit per charger-year (blended DC/AC, from EV_Pilot) | B40: RM | C40: =EV_Pilot!$B$50 -> 8979.74 | D40: =EV_Pilot!$B$50 -> 8979.74 | E40: =EV_Pilot!$B$50 -> 8979.74 | F40: =EV_Pilot!$B$50 -> 8979.74 | G40: =EV_Pilot!$B$50 -> 8979.74
A41: Residents' share of charging profit (their 50%, before the 70/10/10/10 split) | B41: RM | C41: =C39*EV_Pilot!$B$54 -> 2244.935 | D41: =D39*EV_Pilot!$B$54 -> 8979.74 | E41: =E39*EV_Pilot!$B$54 -> 17959.48 | F41: =F39*EV_Pilot!$B$54 -> 26939.22 | G41: =G39*EV_Pilot!$B$54 -> 35918.96
...

Sheet EV_Pilot
A1: EV_Pilot – one charger's economics, who gets the money, and stress tests
A2: Each column is a case. B = normal, C = conservative (all stresses together, from Pools_Scenarios). D–K change one thing from normal. L removes the deferral, M is the worst case, N removes the top-up. Every cell is a formula.
A4: Item | B4: Normal | C4: Conservative (all stresses) | D4: Tariff +20% | E4: Maintenance +50% | F4: Downtime 10% | G4: Price −20% | H4: Grant not approved | I4: Usage 30 kWh/day | J4: No idle or membership fees | K4: Mall MV demand charge | L4: Normal, no deferral (70% split from day 1) | M4: WORST CASE: RM1.00/kWh, tariff +30%, 20 kWh/day, no grant, CPO exits | N4: Conservative, no top-up | O4: Unit / how
A5: Usage and prices
A6: Charging sessions per charger per day | B6: =Assumptions!$B$105 -> 2 | C6: =Pools_Scenarios!$C$93 -> 1.5 | D6: =Assumptions!$B$105 -> 2 | E6: =Assumptions!$B$105 -> 2 | F6: =Assumptions!$B$105 -> 2 | G6: =Assumptions!$B$105 -> 2 | H6: =Assumptions!$B$105 -> 2 | I6: =Pools_Scenarios!$C$93 -> 1.5 | J6: =Assumptions!$B$105 -> 2 | K6: =Assumptions!$B$105 -> 2 | L6: =Assumptions!$B$105 -> 2 | M6: =1 -> 1 | N6: =Pools_Scenarios!$C$93 -> 1.5 | O6: sessions
A7: Energy per session | B7: =Assumptions!$B$106 -> 30 | C7: =Pools_Scenarios!$C$94 -> 20 | D7: =Assumptions!$B$106 -> 30 | E7: =Assumptions!$B$106 -> 30 | F7: =Assumptions!$B$106 -> 30 | G7: =Assumptions!$B$106 -> 30 | H7: =Assumptions!$B$106 -> 30 | I7: =Pools_Scenarios!$C$94 -> 20 | J7: =Assumptions!$B$106 -> 30 | K7: =Assumptions!$B$106 -> 30 | L7: =Assumptions!$B$106 -> 30 | M7: =20 -> 20 | N7: =Pools_Scenarios!$C$94 -> 20 | O7: kWh
A8: Downtime | B8: =0 -> 0 | C8: =Pools_Scenarios!$C$97 -> 0.1 | D8: =0 -> 0 | E8: =0 -> 0 | F8: =Pools_Scenarios!$C$97 -> 0.1 | G8: =0 -> 0 | H8: =0 -> 0 | I8: =0 -> 0 | J8: =0 -> 0 | K8: =0 -> 0 | L8: =0 -> 0 | M8: =Pools_Scenarios!$C$97 -> 0.1 | N8: =Pools_Scenarios!$C$97 -> 0.1 | O8: % of time
A9: Energy sold per charger per day | B9: =B6*B7*(1-B8) -> 60 | C9: =C6*C7*(1-C8) -> 27 | D9: =D6*D7*(1-D8) -> 60 | E9: =E6*E7*(1-E8) -> 60 | F9: =F6*F7*(1-F8) -> 54 | G9: =G6*G7*(1-G8) -> 60 | H9: =H6*H7*(1-H8) -> 60 | I9: =I6*I7*(1-I8) -> 30 | ... N9: =N6*N7*(1-N8) -> 27 | O9: kWh/day
A10: Price level (1 − competitor price drop) | B10: =1-0 -> 1 | C10: =1-Pools_Scenarios!$C$89 -> 0.8 | D10: =1-0 -> 1 | E10: =1-0 -> 1 | F10: =1-0 -> 1 | G10: =1-Pools_Scenarios!$C$89 -> 0.8 | H10: =1-0 -> 1 | I10: =1-0 -> 1 | J10: =1-0 -> 1 | K10: =1-0 -> 1 | L10: =1-0 -> 1 | M10: =1-0 -> 1 | N10: =1-Pools_Scenarios!$C$89 -> 0.8
A11: DC average price (standard + peak) | B11: =IF(0=1,1,(Assumptions!$B$32*(1-Assumptions!$B$120)+Assumptions!$B$119*Assumptions!$B$120)*B10) -> 1.49 | C11: =IF(0=1,1,(Assumptions!$B$32*(1-Assumptions!$B$120)+Assumptions!$B$119*Assumptions!$B$120)*C10) -> 1.192 | D11: =IF(0=1,1,(Assumptions!$B$32*(1-Assumptions!$B$120)+Assumptions!$B$119*Assumptions!$B$120)*D10) -> 1.49 | E11: =IF(0=1,1,(Assumptions!$B$32*(1-Assumptions!$B$120)+Assumptions!$B$119*Assumptions!$B$120)*E10) -> 1.49 | F11: =IF(0=1,1,(Assumptions!$B$32*(1-Assumptions!$B$120)+Assumptions!$B$119*Assumptions!$B$120)*F10) -> 1.49 | G11: =IF(0=1,1,(Assumptions!$B$32*(1-Assumptions!$B$120)+Assumptions!$B$119*Assumptions!$B$120)*G10) -> 1.192 | H11: =IF(0=1,1,(Assumptions!$B$32*(1-Assumptions!$B$120)+Assumptions!$B$119*Assumptions!$B$120)*H10) -> 1.49 | I11: =IF(0=1,1,(Assumptions!$B$32*(1-Assumptions!$B$120)+Assumptions!$B$119*Assumptions!$B$120)*I10) -> 1.49 | ... L11: =IF(0=1,1,(Assumptions!$B$32*(1-Assumptions!$B$120)+Assumptions!$B$119*Assumptions!$B$120)*L10) -> 1.49 | M11: =IF(1=1,1,(Assumptions!$B$32*(1-Assumptions!$B$120)+Assumptions!$B$119*Assumptions!$B$120)*M10) -> 1 | N11: =IF(0=1,1,(Assumptions!$B$32*(1-Assumptions!$B$120)+Assumptions!$B$119*Assumptions!$B$120)*N10) -> 1.192 | O11: RM/kWh
A12: AC average price (standard + off-peak) | B12: =IF(0=1,1,(Assumptions!$B$118*(1-Assumptions!$B$122)+Assumptions!$B$121*Assumptions!$B$122)*B10) -> 0.95 | C12: =IF(0=1,1,(Assumptions!$B$118*(1-Assumptions!$B$122)+Assumptions!$B$121*Assumptions!$B$122)*C10) -> 0.76 | D12: =IF(0=1,1,(Assumptions!$B$118*(1-Assumptions!$B$122)+Assumptions!$B$121*Assumptions!$B$122)*D10) -> 0.95 | E12: =IF(0=1,1,(Assumptions!$B$118*(1-Assumptions!$B$122)+Assumptions!$B$121*Assumptions!$B$122)*E10) -> 0.95 | F12: =IF(0=1,1,(Assumptions!$B$118*(1-Assumptions!$B$122)+Assumptions!$B$121*Assumptions!$B$122)*F10) -> 0.95 | G12: =IF(0=1,1,(Assumptions!$B$118*(1-Assumptions!$B$122)+Assumptions!$B$121*Assumptions!$B$122)*G10) -> 0.76 | H12: =IF(0=1,1,(Assumptions!$B$118*(1-Assumptions!$B$122)+Assumptions!$B$121*Assumptions!$B$122)*H10) -> 0.95 | I12: =IF(0=1,1,(Assumptions!$B$118*(1-Assumptions!$B$122)+Assumptions!$B$121*Assumptions!$B$122)*I10) -> 0.95 | ... L12: =IF(0=1,1,(Assumptions!$B$118*(1-Assumptions!$B$122)+Assumptions!$B$121*Assumptions!$B$122)*L10) -> 0.95 | M12: =IF(1=1,1,(Assumptions!$B$118*(1-Assumptions!$B$122)+Assumptions!$B$121*Assumptions!$B$122)*M10) -> 1 | N12: =IF(0=1,1,(Assumptions!$B$118*(1-Assumptions!$B$122)+Assumptions!$B$121*Assumptions!$B$122)*N10) -> 0.76 | O12: RM/kWh
A13: Electricity cost per kWh (energy + capacity + network) | B13: =Assumptions!$B$102*(1+0) -> 0.5068 | C13: =Assumptions!$B$102*(1+Pools_Scenarios!$C$95) -> 0.60816 | D13: =Assumptions!$B$102*(1+Pools_Scenarios!$C$95) -> 0.60816 | E13: =Assumptions!$B$102*(1+0) -> 0.5068 | F13: =Assumptions!$B$102*(1+0) -> 0.5068 | G13: =Assumptions!$B$102*(1+0) -> 0.5068 | H13: =Assumptions!$B$102*(1+0) -> 0.5068 | I13: =Assumptions!$B$102*(1+0) -> 0.5068 | J13: =Assumptions!$B$102*(1+0) -> 0.5068 | K13: =Assumptions!$B$102*(1+0) -> 0.5068 | L13: =Assumptions!$B$102*(1+0) -> 0.5068 | M13: =Assumptions!$B$102*(1+0.3) -> 0.65884 | N13: =Assumptions!$B$102*(1+Pools_Scenarios!$C$95) -> 0.60816 | O13: RM/kWh
A14: of which capacity charge | B14: =Assumptions!$B$103*(1+0) -> 0.0883 | C14: =Assumptions!$B$103*(1+Pools_Scenarios!$C$95) -> 0.10596 | D14: =Assumptions!$B$103*(1+Pools_Scenarios!$C$95) -> 0.10596 | E14: =Assumptions!$B$103*(1+0) -> 0.0883 | F14: =Assumptions!$B$103*(1+0) -> 0.0883 | G14: =Assumptions!$B$103*(1+0) -> 0.0883 | H14: =Assumptions!$B$103*(1+0) -> 0.0883 | I14: =Assumptions!$B$103*(1+0) -> 0.0883 | J14: =Assumptions!$B$103*(1+0) -> 0.0883 | K14: =Assumptions!$B$103*(1+0) -> 0.0883 | L14: =Assumptions!$B$103*(1+0) -> 0.0883 | M14: =Assumptions!$B$103*(1+0.3) -> 0.11479 | N14: =Assumptions!$B$103*(1+Pools_Scenarios!$C$95) -> 0.10596 | O14: RM/kWh
A15: Maximum-demand charge per kW (only if the site is on the MV tariff) | B15: =0*Assumptions!$B$141 -> 0 | C15: =0*Assumptions!$B$141 -> 0 | D15: =0*Assumptions!$B$141 -> 0 | E15: =0*Assumptions!$B$141 -> 0 | F15: =0*Assumptions!$B$141 -> 0 | G15: =0*Assumptions!$B$141 -> 0 | H15: =0*Assumptions!$B$141 -> 0 | I15: =0*Assumptions!$B$141 -> 0 | J15: =0*Assumptions!$B$141 -> 0 | K15: =1*Assumptions!$B$141 -> 89.27 | L15: =0*Assumptions!$B$141 -> 0 | M15: =0*Assumptions!$B$141 -> 0 | N15: =0*Assumptions!$B$141 -> 0 | O15: RM/kW/month
A16: DC 60 kW charger (per year)
A17: Installed cost | B17: =Assumptions!$B$116 -> 100000 | C17: =Assumptions!$B$116 -> 100000 | D17: =Assumptions!$B$116 -> 100000 | E17: =Assumptions!$B$116 -> 100000 | F17: =Assumptions!$B$116 -> 100000 | G17: =Assumptions!$B$116 -> 100000 | H17: =Assumptions!$B$116 -> 100000 | I17: =Assumptions!$B$116 -> 100000 | ... N17: =Assumptions!$B$116 -> 100000 | O17: RM
A18: MARii grant (if approved) | B18: =MIN(Assumptions!$B$116*Assumptions!$B$104,Assumptions!$B$129)*1 -> 50000 | C18: =MIN(Assumptions!$B$116*Assumptions!$B$104,Assumptions!$B$129)*Pools_Scenarios!$C$98 -> 0 | D18: =MIN(Assumptions!$B$116*Assumptions!$B$104,Assumptions!$B$129)*1 -> 50000 | E18: =MIN(Assumptions!$B$116*Assumptions!$B$104,Assumptions!$B$129)*1 -> 50000 | F18: =MIN(Assumptions!$B$116*Assumptions!$B$104,Assumptions!$B$129)*1 -> 50000 | G18: =MIN(Assumptions!$B$116*Assumptions!$B$104,Assumptions!$B$129)*1 -> 50000 | H18: =MIN(Assumptions!$B$116*Assumptions!$B$104,Assumptions!$B$129)*Pools_Scenarios!$C$98 -> 0 | I18: =MIN(Assumptions!$B$116*Assumptions!$B$104,Assumptions!$B$129)*1 -> 50000 | J18: =MIN(Assumptions!$B$116*Assumptions!$B$104,Assumptions!$B$129)*1 -> 50000 | K18: =MIN(Assumptions!$B$116*Assumptions!$B$104,Assumptions!$B$129)*1 -> 50000 | L18: =MIN(Assumptions!$B$116*Assumptions!$B$104,Assumptions!$B$129)*1 -> 50000 | M18: =MIN(Assumptions!$B$116*Assumptions!$B$104,Assumptions!$B$129)*0 -> 0 | N18: =MIN(Assumptions!$B$116*Assumptions!$B$104,Assumptions!$B$129)*Pools_Scenarios!$C$98 -> 0 | O18: RM
A19: Compliance cost share (per site ÷ chargers per site) | B19: =Assumptions!$B$107/Assumptions!$B$128 -> 7500 | C19: =Assumptions!$B$107/Assumptions!$B$128 -> 7500 | D19: =Assumptions!$B$107/Assumptions!$B$128 -> 7500 | E19: =Assumptions!$B$107/Assumptions!$B$128 -> 7500 | F19: =Assumptions!$B$107/Assumptions!$B$128 -> 7500 | G19: =Assumptions!$B$107/Assumptions!$B$128 -> 7500 | H19: =Assumptions!$B$107/Assumptions!$B$128 -> 7500 | I19: =Assumptions!$B$107/Assumptions!$B$128 -> 7500 | ... N19: =Assumptions!$B$107/Assumptions!$B$128 -> 7500 | O19: RM
A20: Net installed cost | B20: =B17-B18+B19 -> 57500 | C20: =C17-C18+C19 -> 107500 | D20: =D17-D18+D19 -> 57500 | E20: =E17-E18+E19 -> 57500 | F20: =F17-F18+F19 -> 57500 | G20: =G17-G18+G19 -> 57500 | H20: =H17-H18+H19 -> 107500 | I20: =I17-I18+I19 -> 57500 | ... N20: =N17-N18+N19 -> 107500 | O20: RM
A21: Charging revenue | B21: =365*B9*B11 -> 32631 | C21: =365*C9*C11 -> 11747.16 | D21: =365*D9*D11 -> 32631 | E21: =365*E9*E11 -> 32631 | F21: =365*F9*F11 -> 29367.9 | G21: =365*G9*G11 -> 26104.8 | H21: =365*H9*H11 -> 32631 | I21: =365*I9*I11 -> 16315.5 | ... N21: =365*N9*N11 -> 11747.16 | O21: RM/yr
A22: Idle (occupancy) fees | B22: =365*Assumptions!$B$124*Assumptions!$B$123*(1-B8) -> 1460 | C22: =365*Pools_Scenarios!$C$99*Assumptions!$B$123*(1-C8) -> 657 | D22: =365*Assumptions!$B$124*Assumptions!$B$123*(1-D8) -> 1460 | E22: =365*Assumptions!$B$124*Assumptions!$B$123*(1-E8) -> 1460 | F22: =365*Assumptions!$B$124*Assumptions!$B$123*(1-F8) -> 1314 | G22: =365*Assumptions!$B$124*Assumptions!$B$123*(1-G8) -> 1460 | H22: =365*Assumptions!$B$124*Assumptions!$B$123*(1-H8) -> 1460 | I22: =365*Assumptions!$B$124*Assumptions!$B$123*(1-I8) -> 1460 | J22: =365*0*Assumptions!$B$123*(1-J8) -> 0 | K22: =365*Assumptions!$B$124*Assumptions!$B$123*(1-K8) -> 1460 | L22: =365*Assumptions!$B$124*Assumptions!$B$123*(1-L8) -> 1460 | M22: =365*0*Assumptions!$B$123*(1-M8) -> 0 | N22: =365*Pools_Scenarios!$C$99*Assumptions!$B$123*(1-N8) -> 657 | O22: RM/yr
A23: Membership fees | B23: =Assumptions!$B$126*Assumptions!$B$125*12 -> 1800 | C23: =Pools_Scenarios!$C$100*Assumptions!$B$125*12 -> 900 | D23: =Assumptions!$B$126*Assumptions!$B$125*12 -> 1800 | E23: =Assumptions!$B$126*Assumptions!$B$125*12 -> 1800 | F23: =Assumptions!$B$126*Assumptions!$B$125*12 -> 1800 | G23: =Assumptions!$B$126*Assumptions!$B$125*12 -> 1800 | H23: =Assumptions!$B$126*Assumptions!$B$125*12 -> 1800 | I23: =Assumptions!$B$126*Assumptions!$B$125*12 -> 1800 | J23: =0*Assumptions!$B$125*12 -> 0 | K23: =Assumptions!$B$126*Assumptions!$B$125*12 -> 1800 | L23: =Assumptions!$B$126*Assumptions!$B$125*12 -> 1800 | M23: =0*Assumptions!$B$125*12 -> 0 | N23: =Pools_Scenarios!$C$100*Assumptions!$B$125*12 -> 900 | O23: RM/yr
A24: Payment and app costs | B24: =-Assumptions!$B$33*(B21+B22+B23) -> -1076.73 | C24: =-Assumptions!$B$33*(C21+C22+C23) -> -399.1248 | D24: =-Assumptions!$B$33*(D21+D22+D23) -> -1076.73 | E24: =-Assumptions!$B$33*(E21+E22+E23) -> -1076.73 | F24: =-Assumptions!$B$33*(F21+F22+F23) -> -974.457 | G24: =-Assumptions!$B$33*(G21+G22+G23) -> -880.944 | H24: =-Assumptions!$B$33*(H21+H22+H23) -> -1076.73 | I24: =-Assumptions!$B$33*(I21+I22+I23) -> -587.265 | ... N24: =-Assumptions!$B$33*(N21+N22+N23) -> -399.1248 | O24: RM/yr
A25: Electricity (incl. capacity and network charges) | B25: =-365*B9*B13 -> -11098.92 | C25: =-365*C9*C13 -> -5993.4168 | D25: =-365*D9*D13 -> -13318.704 | E25: =-365*E9*E13 -> -11098.92 | F25: =-365*F9*F13 -> -9989.028 | G25: =-365*G9*G13 -> -11098.92 | H25: =-365*H9*H13 -> -11098.92 | I25: =-365*I9*I13 -> -5549.46 | ... N25: =-365*N9*N13 -> -5993.4168 | O25: RM/yr
A26: Maximum-demand charge (MV sites only) | B26: =-B15*Assumptions!$B$142*1*12 -> 0 | C26: =-C15*Assumptions!$B$142*1*12 -> 0 | D26: =-D15*Assumptions!$B$142*1*12 -> 0 | E26: =-E15*Assumptions!$B$142*1*12 -> 0 | F26: =-F15*Assumptions!$B$142*1*12 -> 0 | G26: =-G15*Assumptions!$B$142*1*12 -> 0 | H26: =-H15*Assumptions!$B$142*1*12 -> 0 | I26: =-I15*Assumptions!$B$142*1*12 -> 0 | ... N26: =-N15*Assumptions!$B$142*1*12 -> 0 | O26: RM/yr
A27: Maintenance and CPO service fee | B27: =-Assumptions!$B$34*(1+0) -> -10000 | C27: =-Assumptions!$B$34*(1+Pools_Scenarios!$C$96) -> -15000 | D27: =-Assumptions!$B$34*(1+0) -> -10000 | E27: =-Assumptions!$B$34*(1+Pools_Scenarios!$C$96) -> -15000 | F27: =-Assumptions!$B$34*(1+0) -> -10000 | G27: =-Assumptions!$B$34*(1+0) -> -10000 | H27: =-Assumptions!$B$34*(1+0) -> -10000 | I27: =-Assumptions!$B$34*(1+0) -> -10000 | J27: =-Assumptions!$B$34*(1+0) -> -10000 | K27: =-Assumptions!$B$34*(1+0) -> -10000 | L27: =-Assumptions!$B$34*(1+0) -> -10000 | M27: =-Assumptions!$B$34*(1+Pools_Scenarios!$C$96) -> -15000 | N27: =-Assumptions!$B$34*(1+Pools_Scenarios!$C$96) -> -15000 | O27: RM/yr
A28: Compliance audit share | B28: =-Assumptions!$B$108/Assumptions!$B$128 -> -2500 | C28: =-Assumptions!$B$108/Assumptions!$B$128 -> -2500 | D28: =-Assumptions!$B$108/Assumptions!$B$128 -> -2500 | E28: =-Assumptions!$B$108/Assumptions!$B$128 -> -2500 | F28: =-Assumptions!$B$108/Assumptions!$B$128 -> -2500 | G28: =-Assumptions!$B$108/Assumptions!$B$128 -> -2500 | H28: =-Assumptions!$B$108/Assumptions!$B$128 -> -2500 | I28: =-Assumptions!$B$108/Assumptions!$B$128 -> -2500 | ... N28: =-Assumptions!$B$108/Assumptions!$B$128 -> -2500 | O28: RM/yr
A29: Net charging profit | B29: =SUM(B21:B28) -> 11215.35 | C29: =SUM(C21:C28) -> -10588.382 | D29: =SUM(D21:D28) -> 8995.566 | E29: =SUM(E21:E28) -> 6215.35 | F29: =SUM(F21:F28) -> 9018.415 | G29: =SUM(G21:G28) -> 4884.936 | H29: =SUM(H21:H28) -> 11215.35 | I29: =SUM(I21:I28) -> 938.775 | ... N29: =SUM(N21:N28) -> -10588.382 | O29: RM/yr
A30: Revenue per charger per day | B30: =(B21+B22+B23)/365 -> 98.331507 | C30: =(C21+C22+C23)/365 -> 36.449753 | D30: =(D21+D22+D23)/365 -> 98.331507 | E30: =(E21+E22+E23)/365 -> 98.331507 | F30: =(F21+F22+F23)/365 -> 88.991507 | G30: =(G21+G22+G23)/365 -> 80.451507 | H30: =(H21+H22+H23)/365 -> 98.331507 | I30: =(I21+I22+I23)/365 -> 53.631507 | ... N30: =(N21+N22+N23)/365 -> 36.449753 | O30: RM/day
A31: AC 22 kW charger (per year)
A32: Installed cost | B32: =Assumptions!$B$117 -> 25000 | C32: =Assumptions!$B$117 -> 25000 | D32: =Assumptions!$B$117 -> 25000 | E32: =Assumptions!$B$117 -> 25000 | F32: =Assumptions!$B$117 -> 25000 | G32: =Assumptions!$B$117 -> 25000 | H32: =Assumptions!$B$117 -> 25000 | I32: =Assumptions!$B$117 -> 25000 | ... N32: =Assumptions!$B$117 -> 25000 | O32: RM
A33: Compliance cost share (per site ÷ chargers per site) | B33: =Assumptions!$B$107/Assumptions!$B$128 -> 7500 | C33: =Assumptions!$B$107/Assumptions!$B$128 -> 7500 | D33: =Assumptions!$B$107/Assumptions!$B$128 -> 7500 | E33: =Assumptions!$B$107/Assumptions!$B$128 -> 7500 | F33: =Assumptions!$B$107/Assumptions!$B$128 -> 7500 | G33: =Assumptions!$B$107/Assumptions!$B$128 -> 7500 | H33: =Assumptions!$B$107/Assumptions!$B$128 -> 7500 | I33: =Assumptions!$B$107/Assumptions!$B$128 -> 7500 | ... N33: =Assumptions!$B$107/Assumptions!$B$128 -> 7500 | O33: RM
A34: Net installed cost | B34: =B32+B33 -> 32500 | C34: =C32+C33 -> 32500 | D34: =D32+D33 -> 32500 | E34: =E32+E33 -> 32500 | F34: =F32+F33 -> 32500 | G34: =G32+G33 -> 32500 | H34: =H32+H33 -> 32500 | I34: =I32+I33 -> 32500 | ... N34: =N32+N33 -> 32500 | O34: RM
A35: Charging revenue | B35: =365*B9*B12 -> 20805 | C35: =365*C9*C12 -> 7489.8 | D35: =365*D9*D12 -> 20805 | E35: =365*E9*E12 -> 20805 | F35: =365*F9*F12 -> 18724.5 | G35: =365*G9*G12 -> 16644 | H35: =365*H9*H12 -> 20805 | I35: =365*I9*I12 -> 10402.5 | ... N35: =365*N9*N12 -> 7489.8 | O35: RM/yr
A36: Idle (occupancy) fees | B36: =365*Assumptions!$B$124*Assumptions!$B$123*(1-B8) -> 1460 | C36: =365*Pools_Scenarios!$C$99*Assumptions!$B$123*(1-C8) -> 657 | D36: =365*Assumptions!$B$124*Assumptions!$B$123*(1-D8) -> 1460 | E36: =365*Assumptions!$B$124*Assumptions!$B$123*(1-E8) -> 1460 | F36: =365*Assumptions!$B$124*Assumptions!$B$123*(1-F8) -> 1314 | G36: =365*Assumptions!$B$124*Assumptions!$B$123*(1-G8) -> 1460 | H36: =365*Assumptions!$B$124*Assumptions!$B$123*(1-H8) -> 1460 | I36: =365*Assumptions!$B$124*Assumptions!$B$123*(1-I8) -> 1460 | J36: =365*0*Assumptions!$B$123*(1-J8) -> 0 | K36: =365*Assumptions!$B$124*Assumptions!$B$123*(1-K8) -> 1460 | L36: =365*Assumptions!$B$124*Assumptions!$B$123*(1-L8) -> 1460 | M36: =365*0*Assumptions!$B$123*(1-M8) -> 0 | N36: =365*Pools_Scenarios!$C$99*Assumptions!$B$123*(1-N8) -> 657 | O36: RM/yr
A37: Membership fees | B37: =Assumptions!$B$126*Assumptions!$B$125*12 -> 1800 | C37: =Pools_Scenarios!$C$100*Assumptions!$B$125*12 -> 900 | D37: =Assumptions!$B$126*Assumptions!$B$125*12 -> 1800 | E37: =Assumptions!$B$126*Assumptions!$B$125*12 -> 1800 | F37: =Assumptions!$B$126*Assumptions!$B$125*12 -> 1800 | G37: =Assumptions!$B$126*Assumptions!$B$125*12 -> 1800 | H37: =Assumptions!$B$126*Assumptions!$B$125*12 -> 1800 | I37: =Assumptions!$B$126*Assumptions!$B$125*12 -> 1800 | J37: =0*Assumptions!$B$125*12 -> 0 | K37: =Assumptions!$B$126*Assumptions!$B$125*12 -> 1800 | L37: =Assumptions!$B$126*Assumptions!$B$125*12 -> 1800 | M37: =0*Assumptions!$B$125*12 -> 0 | N37: =Pools_Scenarios!$C$100*Assumptions!$B$125*12 -> 900 | O37: RM/yr
A38: Payment and app costs | B38: =-Assumptions!$B$33*(B35+B36+B37) -> -721.95 | C38: =-Assumptions!$B$33*(C35+C36+C37) -> -271.404 | D38: =-Assumptions!$B$33*(D35+D36+D37) -> -721.95 | E38: =-Assumptions!$B$33*(E35+E36+E37) -> -721.95 | F38: =-Assumptions!$B$33*(F35+F36+F37) -> -655.155 | G38: =-Assumptions!$B$33*(G35+G36+G37) -> -597.12 | H38: =-Assumptions!$B$33*(H35+H36+H37) -> -721.95 | I38: =-Assumptions!$B$33*(I35+I36+I37) -> -409.875 | ... N38: =-Assumptions!$B$33*(N35+N36+N37) -> -271.404 | O38: RM/yr
A39: Electricity (incl. capacity and network charges) | B39: =-365*B9*B13 -> -11098.92 | C39: =-365*C9*C13 -> -5993.4168 | D39: =-365*D9*D13 -> -13318.704 | E39: =-365*E9*E13 -> -11098.92 | F39: =-365*F9*F13 -> -9989.028 | G39: =-365*G9*G13 -> -11098.92 | H39: =-365*H9*H13 -> -11098.92 | I39: =-365*I9*I13 -> -5549.46 | ... N39: =-365*N9*N13 -> -5993.4168 | O39: RM/yr
A40: Maximum-demand charge (MV sites only) | B40: =-B15*Assumptions!$B$142*22/60*12 -> 0 | C40: =-C15*Assumptions!$B$142*22/60*12 -> 0 | D40: =-D15*Assumptions!$B$142*22/60*12 -> 0 | E40: =-E15*Assumptions!$B$142*22/60*12 -> 0 | F40: =-F15*Assumptions!$B$142*22/60*12 -> 0 | G40: =-G15*Assumptions!$B$142*22/60*12 -> 0 | H40: =-H15*Assumptions!$B$142*22/60*12 -> 0 | I40: =-I15*Assumptions!$B$142*22/60*12 -> 0 | ... N40: =-N15*Assumptions!$B$142*22/60*12 -> 0 | O40: RM/yr
A41: Maintenance and CPO service fee | B41: =-Assumptions!$B$127*(1+0) -> -3000 | C41: =-Assumptions!$B$127*(1+Pools_Scenarios!$C$96) -> -4500 | D41: =-Assumptions!$B$127*(1+0) -> -3000 | E41: =-Assumptions!$B$127*(1+Pools_Scenarios!$C$96) -> -4500 | F41: =-Assumptions!$B$127*(1+0) -> -3000 | G41: =-Assumptions!$B$127*(1+0) -> -3000 | H41: =-Assumptions!$B$127*(1+0) -> -3000 | I41: =-Assumptions!$B$127*(1+0) -> -3000 | J41: =-Assumptions!$B$127*(1+0) -> -3000 | K41: =-Assumptions!$B$127*(1+0) -> -3000 | L41: =-Assumptions!$B$127*(1+0) -> -3000 | M41: =-Assumptions!$B$127*(1+Pools_Scenarios!$C$96) -> -4500 | N41: =-Assumptions!$B$127*(1+Pools_Scenarios!$C$96) -> -4500 | O41: RM/yr
...

Sheet Benefits
A1: 1) Benefits – value created for the developer (customer)
A2: Top: one SDP-size client by its year on the platform. Bottom: all clients together by calendar year.
A4: Benefit | B4: How it is worked out | C4: Year 1 | D4: Year 2 | E4: Year 3 | F4: Year 4 | G4: Year 5
A5: One SDP-size client (by client's year)
A6: A. Cheaper money for solar | B6: Residents' solar money × ((8.5% − 5%) × developer's JV share + JV arrangement fee) | C6: =Pools_Scenarios!C18*((Assumptions!$B$21-Assumptions!$B$19)*Assumptions!$B$14+Assumptions!$B$70) -> 39600 | D6: =Pools_Scenarios!D18*((Assumptions!$B$21-Assumptions!$B$19)*Assumptions!$B$14+Assumptions!$B$70) -> 111633.4 | E6: =Pools_Scenarios!E18*((Assumptions!$B$21-Assumptions!$B$19)*Assumptions!$B$14+Assumptions!$B$70) -> 182175.26 | F6: =Pools_Scenarios!F18*((Assumptions!$B$21-Assumptions!$B$19)*Assumptions!$B$14+Assumptions!$B$70) -> 261302.15 | G6: =Pools_Scenarios!G18*((Assumptions!$B$21-Assumptions!$B$19)*Assumptions!$B$14+Assumptions!$B$70) -> 330145.57
A7: B. Fee from shop upgrades | B7: Shop-years × positive safety margin × developer's share | C7: =Pools_Scenarios!C28*MAX(0,Pools_Scenarios!C31)*Assumptions!$B$28 -> 8415.8974 | D7: =Pools_Scenarios!D28*MAX(0,Pools_Scenarios!D31)*Assumptions!$B$28 -> 30858.291 | E7: =Pools_Scenarios!E28*MAX(0,Pools_Scenarios!E31)*Assumptions!$B$28 -> 50495.384 | F7: =Pools_Scenarios!F28*MAX(0,Pools_Scenarios!F31)*Assumptions!$B$28 -> 53300.684 | G7: =Pools_Scenarios!G28*MAX(0,Pools_Scenarios!G31)*Assumptions!$B$28 -> 42079.487
A8: C. Developer's EV share, less its part of the usage top-up | B8: 10% of residents' EV profit (paid after residents recover) − developer's 33% of any top-up | C8: =Pools_Scenarios!C70-Pools_Scenarios!C71 -> 0 | D8: =Pools_Scenarios!D70-Pools_Scenarios!D71 -> 0 | E8: =Pools_Scenarios!E70-Pools_Scenarios!E71 -> 0 | F8: =Pools_Scenarios!F70-Pools_Scenarios!F71 -> 0 | G8: =Pools_Scenarios!G70-Pools_Scenarios!G71 -> 0
A9: D. Extra mall rent | B9: Money spent at malls × turnover rent | C9: =Pools_Scenarios!C48*Assumptions!$B$10 -> 1286.3148 | D9: =Pools_Scenarios!D48*Assumptions!$B$10 -> 3986.9818 | E9: =Pools_Scenarios!E48*Assumptions!$B$10 -> 6999.4954 | F9: =Pools_Scenarios!F48*Assumptions!$B$10 -> 10379.627 | G9: =Pools_Scenarios!G48*Assumptions!$B$10 -> 13822.198
A10: Cash benefits (A to D, plus F, less G) | C10: =SUM(C6:C9)+C31+C34 -> 42768.55 | D10: =SUM(D6:D9)+D31+D34 -> 126156.78 | E10: =SUM(E6:E9)+E31+E34 -> 203981.54 | F10: =SUM(F6:F9)+F31+F34 -> 271239.97 | G10: =SUM(G6:G9)+G31+G34 -> 312421.29
A11: E. Community-programme saving (actually achieved) | B11: Programme spend × saving rate × share achieved | C11: =Assumptions!$B$13*Assumptions!$B$158*Assumptions!$B$64 -> 104000 | D11: =Assumptions!$B$13*Assumptions!$C$158*Assumptions!$B$64 -> 208000 | E11: =Assumptions!$B$13*Assumptions!$D$158*Assumptions!$B$64 -> 208000 | F11: =Assumptions!$B$13*Assumptions!$E$158*Assumptions!$B$64 -> 208000 | G11: =Assumptions!$B$13*Assumptions!$F$158*Assumptions!$B$64 -> 208000
A12: Total benefit for one SDP-size client | C12: =C10+C11 -> 146768.55 | D12: =D10+D11 -> 334156.78 | E12: =E10+E11 -> 411981.54 | F12: =F10+F11 -> 479239.97 | G12: =G10+G11 -> 520421.29
A14: Value to residents and shops (one SDP-size client, not counted in developer ROI)
A15: Residents' profit earned | B15: Payout profit on money invested, after expected shop losses | C15: =Pools_Scenarios!C50 -> 82163.299 | D15: =Pools_Scenarios!D50 -> 237325.4 | E15: =Pools_Scenarios!E50 -> 378613.85 | F15: =Pools_Scenarios!F50 -> 517911.11 | G15: =Pools_Scenarios!G50 -> 636879.55
A16: Savings shops keep | B16: 20% of savings during repayment | C16: =Pools_Scenarios!C32 -> 18000 | D16: =Pools_Scenarios!D32 -> 66000 | E16: =Pools_Scenarios!E32 -> 108000 | F16: =Pools_Scenarios!F32 -> 114000 | G16: =Pools_Scenarios!G32 -> 90000
A17: CO2 avoided (tCO2e) | B17: Solar + upgrades | C17: =Pools_Scenarios!C51 -> 1518.9128 | D17: =Pools_Scenarios!D51 -> 4644.3469 | E17: =Pools_Scenarios!E51 -> 8188.4767 | F17: =Pools_Scenarios!F51 -> 12394.781 | G17: =Pools_Scenarios!G51 -> 16844.564
A19: All clients together (by calendar year)
A20: Developer clients on the platform | B20: Cumulative clients signed | C20: =Assumptions!$B$159 -> 1 | D20: =Assumptions!$B$159+Assumptions!$C$159 -> 3 | E20: =Assumptions!$B$159+Assumptions!$C$159+Assumptions!$D$159 -> 5 | F20: =Assumptions!$B$159+Assumptions!$C$159+Assumptions!$D$159+Assumptions!$E$159 -> 7 | G20: =Assumptions!$B$159+Assumptions!$C$159+Assumptions!$D$159+Assumptions!$E$159+Assumptions!$F$159 -> 9
A21: Cash benefits (A to D, plus F), all clients | C21: =Assumptions!$B$159*Assumptions!$B$160*C10 -> 42768.55 | D21: =Assumptions!$B$159*Assumptions!$B$160*D10+Assumptions!$C$159*Assumptions!$C$160*C10 -> 177479.04 | E21: =Assumptions!$B$159*Assumptions!$B$160*E10+Assumptions!$C$159*Assumptions!$C$160*D10+Assumptions!$D$159*Assumptions!$D$160*C10 -> 406691.94 | F21: =Assumptions!$B$159*Assumptions!$B$160*F10+Assumptions!$C$159*Assumptions!$C$160*E10+Assumptions!$D$159*Assumptions!$D$160*D10+Assumptions!$E$159*Assumptions!$E$160*C10 -> 718728.22 | G21: =Assumptions!$B$159*Assumptions!$B$160*G10+Assumptions!$C$159*Assumptions!$C$160*F10+Assumptions!$D$159*Assumptions!$D$160*E10+Assumptions!$E$159*Assumptions!$E$160*D10+Assumptions!$F$159*Assumptions!$F$160*C10 -> 1085397.5
